Workbook
Name A: 'HTBar Individual'!$N$1

Sheet HTBar
A1: Given Data | D1: Month | E1: Jan | F1: Feb | G1: Mar | H1: Apr | I1: May | J1: Jun | K1: Jul | L1: Aug | M1: Sep | N1: Oct | O1: Nov | P1: Dec
A2: Latitude | B2: 48.55 | D2: Hbar (kWh/m2) | E2: 1.44 | F2: 2.35 | G2: 3.57 | H2: 4.65 | I2: 5.07 | J2: 5.46 | K2: 4.97 | L2: 4.46 | M2: 3.23 | N2: 1.95 | O2: 1.31 | P2: 1.11
A3: Longitude | B3: 71.65 | D3: Hbar (MJ/m2) | E3: =PRODUCT(E2,3.6) -> 5.184 | F3: =PRODUCT(F2,3.6) -> 8.46 | G3: =PRODUCT(G2,3.6) -> 12.852 | H3: =PRODUCT(H2,3.6) -> 16.74 | I3: =PRODUCT(I2,3.6) -> 18.252 | J3: =PRODUCT(J2,3.6) -> 19.656 | K3: =PRODUCT(K2,3.6) -> 17.892 | L3: =PRODUCT(L2,3.6) -> 16.056 | ... P3: =PRODUCT(P2,3.6) -> 3.996 | R3: OmegaSdash | S3: =$A$12&TEXT(B12," - ")&B12 -> Beta - 3 | T3: =MIN(DEGREES(ACOS((-TAN($B2*PI()/180))*TAN(E6*PI()/180))),DEGREES(ACOS((-TAN(($B2-$B12)*PI()/180))*TAN(E6*PI()/180)))) -> 64.357072 | U3: =MIN(DEGREES(ACOS((-TAN($B2*PI()/180))*TAN(F6*PI()/180))),DEGREES(ACOS((-TAN(($B2-$B12)*PI()/180))*TAN(F6*PI()/180)))) -> 74.902424 | V3: =MIN(DEGREES(ACOS((-TAN($B2*PI()/180))*TAN(G6*PI()/180))),DEGREES(ACOS((-TAN(($B2-$B12)*PI()/180))*TAN(G6*PI()/180)))) -> 87.259767 | W3: =MIN(DEGREES(ACOS((-TAN($B2*PI()/180))*TAN(H6*PI()/180))),DEGREES(ACOS((-TAN(($B2-$B12)*PI()/180))*TAN(H6*PI()/180)))) -> 99.731449 | X3: =MIN(DEGREES(ACOS((-TAN($B2*PI()/180))*TAN(I6*PI()/180))),DEGREES(ACOS((-TAN(($B2-$B12)*PI()/180))*TAN(I6*PI()/180)))) -> 110.29578 | Y3: =MIN(DEGREES(ACOS((-TAN($B2*PI()/180))*TAN(J6*PI()/180))),DEGREES(ACOS((-TAN(($B2-$B12)*PI()/180))*TAN(J6*PI()/180)))) -> 115.75402 | Z3: =MIN(DEGREES(ACOS((-TAN($B2*PI()/180))*TAN(K6*PI()/180))),DEGREES(ACOS((-TAN(($B2-$B12)*PI()/180))*TAN(K6*PI()/180)))) -> 113.2697 | AA3: =MIN(DEGREES(ACOS((-TAN($B2*PI()/180))*TAN(L6*PI()/180))),DEGREES(ACOS((-TAN(($B2-$B12)*PI()/180))*TAN(L6*PI()/180)))) -> 104.11597 | ... AE3: =MIN(DEGREES(ACOS((-TAN($B2*PI()/180))*TAN(P6*PI()/180))),DEGREES(ACOS((-TAN(($B2-$B12)*PI()/180))*TAN(P6*PI()/180)))) -> 61.198025
A4: Place | B4: BMO (Alma, Quebec) | D4: Pgbar | E4: 0.31 | F4: 0.28 | G4: 0.3 | H4: 0.24 | I4: 0.09 | J4: 0.1 | K4: 0.1 | L4: 0.09 | M4: 0.1 | N4: 0.09 | O4: 0.21 | P4: 0.28 | S4: =$A$12&TEXT(B13," - ")&B13 -> Beta - 6 | T4: =MIN(DEGREES(ACOS((-TAN($B2*PI()/180))*TAN(E6*PI()/180))),DEGREES(ACOS((-TAN(($B2-$B13)*PI()/180))*TAN(E6*PI()/180)))) -> 64.357072 | U4: =MIN(DEGREES(ACOS((-TAN($B2*PI()/180))*TAN(F6*PI()/180))),DEGREES(ACOS((-TAN(($B2-$B13)*PI()/180))*TAN(F6*PI()/180)))) -> 74.902424 | V4: =MIN(DEGREES(ACOS((-TAN($B2*PI()/180))*TAN(G6*PI()/180))),DEGREES(ACOS((-TAN(($B2-$B13)*PI()/180))*TAN(G6*PI()/180)))) -> 87.259767 | W4: =MIN(DEGREES(ACOS((-TAN($B2*PI()/180))*TAN(H6*PI()/180))),DEGREES(ACOS((-TAN(($B2-$B13)*PI()/180))*TAN(H6*PI()/180)))) -> 98.754951 | X4: =MIN(DEGREES(ACOS((-TAN($B2*PI()/180))*TAN(I6*PI()/180))),DEGREES(ACOS((-TAN(($B2-$B13)*PI()/180))*TAN(I6*PI()/180)))) -> 108.20073 | Y4: =MIN(DEGREES(ACOS((-TAN($B2*PI()/180))*TAN(J6*PI()/180))),DEGREES(ACOS((-TAN(($B2-$B13)*PI()/180))*TAN(J6*PI()/180)))) -> 113.03335 | Z4: =MIN(DEGREES(ACOS((-TAN($B2*PI()/180))*TAN(K6*PI()/180))),DEGREES(ACOS((-TAN(($B2-$B13)*PI()/180))*TAN(K6*PI()/180)))) -> 110.83906 | AA4: =MIN(DEGREES(ACOS((-TAN($B2*PI()/180))*TAN(L6*PI()/180))),DEGREES(ACOS((-TAN(($B2-$B13)*PI()/180))*TAN(L6*PI()/180)))) -> 102.68638 | ... AE4: =MIN(DEGREES(ACOS((-TAN($B2*PI()/180))*TAN(P6*PI()/180))),DEGREES(ACOS((-TAN(($B2-$B13)*PI()/180))*TAN(P6*PI()/180)))) -> 61.198025
A5: Gsc | B5: 1367 | D5: nbar | E5: 17 | F5: 47 | G5: 75 | H5: 105 | I5: 135 | J5: 162 | K5: 198 | L5: 228 | M5: 258 | N5: 288 | O5: 318 | P5: 344 | S5: =$A$12&TEXT(B14," - ")&B14 -> Beta - 9 | T5: =MIN(DEGREES(ACOS((-TAN($B2*PI()/180))*TAN(E6*PI()/180))),DEGREES(ACOS((-TAN(($B2-$B14)*PI()/180))*TAN(E6*PI()/180)))) -> 64.357072 | U5: =MIN(DEGREES(ACOS((-TAN($B2*PI()/180))*TAN(F6*PI()/180))),DEGREES(ACOS((-TAN(($B2-$B14)*PI()/180))*TAN(F6*PI()/180)))) -> 74.902424 | V5: =MIN(DEGREES(ACOS((-TAN($B2*PI()/180))*TAN(G6*PI()/180))),DEGREES(ACOS((-TAN(($B2-$B14)*PI()/180))*TAN(G6*PI()/180)))) -> 87.259767 | W5: =MIN(DEGREES(ACOS((-TAN($B2*PI()/180))*TAN(H6*PI()/180))),DEGREES(ACOS((-TAN(($B2-$B14)*PI()/180))*TAN(H6*PI()/180)))) -> 97.870316 | X5: =MIN(DEGREES(ACOS((-TAN($B2*PI()/180))*TAN(I6*PI()/180))),DEGREES(ACOS((-TAN(($B2-$B14)*PI()/180))*TAN(I6*PI()/180)))) -> 106.31968 | Y5: =MIN(DEGREES(ACOS((-TAN($B2*PI()/180))*TAN(J6*PI()/180))),DEGREES(ACOS((-TAN(($B2-$B14)*PI()/180))*TAN(J6*PI()/180)))) -> 110.60938 | Z5: =MIN(DEGREES(ACOS((-TAN($B2*PI()/180))*TAN(K6*PI()/180))),DEGREES(ACOS((-TAN(($B2-$B14)*PI()/180))*TAN(K6*PI()/180)))) -> 108.6652 | AA5: =MIN(DEGREES(ACOS((-TAN($B2*PI()/180))*TAN(L6*PI()/180))),DEGREES(ACOS((-TAN(($B2-$B14)*PI()/180))*TAN(L6*PI()/180)))) -> 101.39497 | ... AE5: =MIN(DEGREES(ACOS((-TAN($B2*PI()/180))*TAN(P6*PI()/180))),DEGREES(ACOS((-TAN(($B2-$B14)*PI()/180))*TAN(P6*PI()/180)))) -> 61.198025
D6: Del | E6: =(23.45*SIN(360*((284+E5)/365)*PI()/180)) -> -20.916963 | F6: =(23.45*SIN(360*((284+F5)/365)*PI()/180)) -> -12.954608 | G6: =(23.45*SIN(360*((284+G5)/365)*PI()/180)) -> -2.4177348 | H6: =(23.45*SIN(360*((284+H5)/365)*PI()/180)) -> 9.4148933 | I6: =(23.45*SIN(360*((284+I5)/365)*PI()/180)) -> 18.791918 | J6: =(23.45*SIN(360*((284+J5)/365)*PI()/180)) -> 23.085911 | K6: =(23.45*SIN(360*((284+K5)/365)*PI()/180)) -> 21.183694 | L6: =(23.45*SIN(360*((284+L5)/365)*PI()/180)) -> 13.45496 | ... P6: =(23.45*SIN(360*((284+P5)/365)*PI()/180)) -> -23.049628 | S6: =$A$12&TEXT(B15," - ")&B15 -> Beta - 12 | T6: =MIN(DEGREES(ACOS((-TAN($B2*PI()/180))*TAN(E6*PI()/180))),DEGREES(ACOS((-TAN(($B2-$B15)*PI()/180))*TAN(E6*PI()/180)))) -> 64.357072 | U6: =MIN(DEGREES(ACOS((-TAN($B2*PI()/180))*TAN(F6*PI()/180))),DEGREES(ACOS((-TAN(($B2-$B15)*PI()/180))*TAN(F6*PI()/180)))) -> 74.902424 | V6: =MIN(DEGREES(ACOS((-TAN($B2*PI()/180))*TAN(G6*PI()/180))),DEGREES(ACOS((-TAN(($B2-$B15)*PI()/180))*TAN(G6*PI()/180)))) -> 87.259767 | W6: =MIN(DEGREES(ACOS((-TAN($B2*PI()/180))*TAN(H6*PI()/180))),DEGREES(ACOS((-TAN(($B2-$B15)*PI()/180))*TAN(H6*PI()/180)))) -> 97.060739 | X6: =MIN(DEGREES(ACOS((-TAN($B2*PI()/180))*TAN(I6*PI()/180))),DEGREES(ACOS((-TAN(($B2-$B15)*PI()/180))*TAN(I6*PI()/180)))) -> 104.6105 | Y6: =MIN(DEGREES(ACOS((-TAN($B2*PI()/180))*TAN(J6*PI()/180))),DEGREES(ACOS((-TAN(($B2-$B15)*PI()/180))*TAN(J6*PI()/180)))) -> 108.42005 | Z6: =MIN(DEGREES(ACOS((-TAN($B2*PI()/180))*TAN(K6*PI()/180))),DEGREES(ACOS((-TAN(($B2-$B15)*PI()/180))*TAN(K6*PI()/180)))) -> 106.69599 | AA6: =MIN(DEGREES(ACOS((-TAN($B2*PI()/180))*TAN(L6*PI()/180))),DEGREES(ACOS((-TAN(($B2-$B15)*PI()/180))*TAN(L6*PI()/180)))) -> 100.21586 | ... AE6: =MIN(DEGREES(ACOS((-TAN($B2*PI()/180))*TAN(P6*PI()/180))),DEGREES(ACOS((-TAN(($B2-$B15)*PI()/180))*TAN(P6*PI()/180)))) -> 61.198025
D7: OmegaS | E7: =DEGREES(ACOS((-TAN($B2*PI()/180))*TAN(E6*PI()/180))) -> 64.357072 | F7: =DEGREES(ACOS((-TAN($B2*PI()/180))*TAN(F6*PI()/180))) -> 74.902424 | G7: =DEGREES(ACOS((-TAN($B2*PI()/180))*TAN(G6*PI()/180))) -> 87.259767 | H7: =DEGREES(ACOS((-TAN($B2*PI()/180))*TAN(H6*PI()/180))) -> 100.82155 | I7: =DEGREES(ACOS((-TAN($B2*PI()/180))*TAN(I6*PI()/180))) -> 112.66129 | J7: =DEGREES(ACOS((-TAN($B2*PI()/180))*TAN(J6*PI()/180))) -> 118.85738 | K7: =DEGREES(ACOS((-TAN($B2*PI()/180))*TAN(K6*PI()/180))) -> 116.02819 | L7: =DEGREES(ACOS((-TAN($B2*PI()/180))*TAN(L6*PI()/180))) -> 105.7176 | ... P7: =DEGREES(ACOS((-TAN($B2*PI()/180))*TAN(P6*PI()/180))) -> 61.198025 | S7: =$A$12&TEXT(B16," - ")&B16 -> Beta - 15 | T7: =MIN(DEGREES(ACOS((-TAN($B2*PI()/180))*TAN(E6*PI()/180))),DEGREES(ACOS((-TAN(($B2-$B16)*PI()/180))*TAN(E6*PI()/180)))) -> 64.357072 | U7: =MIN(DEGREES(ACOS((-TAN($B2*PI()/180))*TAN(F6*PI()/180))),DEGREES(ACOS((-TAN(($B2-$B16)*PI()/180))*TAN(F6*PI()/180)))) -> 74.902424 | V7: =MIN(DEGREES(ACOS((-TAN($B2*PI()/180))*TAN(G6*PI()/180))),DEGREES(ACOS((-TAN(($B2-$B16)*PI()/180))*TAN(G6*PI()/180)))) -> 87.259767 | W7: =MIN(DEGREES(ACOS((-TAN($B2*PI()/180))*TAN(H6*PI()/180))),DEGREES(ACOS((-TAN(($B2-$B16)*PI()/180))*TAN(H6*PI()/180)))) -> 96.312977 | X7: =MIN(DEGREES(ACOS((-TAN($B2*PI()/180))*TAN(I6*PI()/180))),DEGREES(ACOS((-TAN(($B2-$B16)*PI()/180))*TAN(I6*PI()/180)))) -> 103.04095 | Y7: =MIN(DEGREES(ACOS((-TAN($B2*PI()/180))*TAN(J6*PI()/180))),DEGREES(ACOS((-TAN(($B2-$B16)*PI()/180))*TAN(J6*PI()/180)))) -> 106.41909 | Z7: =MIN(DEGREES(ACOS((-TAN($B2*PI()/180))*TAN(K6*PI()/180))),DEGREES(ACOS((-TAN(($B2-$B16)*PI()/180))*TAN(K6*PI()/180)))) -> 104.89203 | AA7: =MIN(DEGREES(ACOS((-TAN($B2*PI()/180))*TAN(L6*PI()/180))),DEGREES(ACOS((-TAN(($B2-$B16)*PI()/180))*TAN(L6*PI()/180)))) -> 99.12883 | ... AE7: =MIN(DEGREES(ACOS((-TAN($B2*PI()/180))*TAN(P6*PI()/180))),DEGREES(ACOS((-TAN(($B2-$B16)*PI()/180))*TAN(P6*PI()/180)))) -> 61.198025
D8: HoBar (MJ/m2) | E8: =(24*3600*1367*(1 + (0.033*COS((360*E5*PI())/(365*180))))*((COS($B2*PI()/180)*COS(E6*PI()/180)*SIN(E7*PI()/180))+((PI()*E7/180)*SIN($B2*PI()/180)*SIN(E6*PI()/180))))/(PI()*1000000) -> 9.9620948 | F8: =(24*3600*1367*(1 + (0.033*COS((360*F5*PI())/(365*180))))*((COS($B2*PI()/180)*COS(F6*PI()/180)*SIN(F7*PI()/180))+((PI()*F7/180)*SIN($B2*PI()/180)*SIN(F6*PI()/180))))/(PI()*1000000) -> 15.503106 | G8: =(24*3600*1367*(1 + (0.033*COS((360*G5*PI())/(365*180))))*((COS($B2*PI()/180)*COS(G6*PI()/180)*SIN(G7*PI()/180))+((PI()*G7/180)*SIN($B2*PI()/180)*SIN(G6*PI()/180))))/(PI()*1000000) -> 23.235569 | H8: =(24*3600*1367*(1 + (0.033*COS((360*H5*PI())/(365*180))))*((COS($B2*PI()/180)*COS(H6*PI()/180)*SIN(H7*PI()/180))+((PI()*H7/180)*SIN($B2*PI()/180)*SIN(H6*PI()/180))))/(PI()*1000000) -> 31.976846 | I8: =(24*3600*1367*(1 + (0.033*COS((360*I5*PI())/(365*180))))*((COS($B2*PI()/180)*COS(I6*PI()/180)*SIN(I7*PI()/180))+((PI()*I7/180)*SIN($B2*PI()/180)*SIN(I6*PI()/180))))/(PI()*1000000) -> 38.696584 | J8: =(24*3600*1367*(1 + (0.033*COS((360*J5*PI())/(365*180))))*((COS($B2*PI()/180)*COS(J6*PI()/180)*SIN(J7*PI()/180))+((PI()*J7/180)*SIN($B2*PI()/180)*SIN(J6*PI()/180))))/(PI()*1000000) -> 41.641344 | K8: =(24*3600*1367*(1 + (0.033*COS((360*K5*PI())/(365*180))))*((COS($B2*PI()/180)*COS(K6*PI()/180)*SIN(K7*PI()/180))+((PI()*K7/180)*SIN($B2*PI()/180)*SIN(K6*PI()/180))))/(PI()*1000000) -> 40.152123 | L8: =(24*3600*1367*(1 + (0.033*COS((360*L5*PI())/(365*180))))*((COS($B2*PI()/180)*COS(L6*PI()/180)*SIN(L7*PI()/180))+((PI()*L7/180)*SIN($B2*PI()/180)*SIN(L6*PI()/180))))/(PI()*1000000) -> 34.568812 | ... P8: =(24*3600*1367*(1 + (0.033*COS((360*P5*PI())/(365*180))))*((COS($B2*PI()/180)*COS(P6*PI()/180)*SIN(P7*PI()/180))+((PI()*P7/180)*SIN($B2*PI()/180)*SIN(P6*PI()/180))))/(PI()*1000000) -> 8.5384218 | S8: =$A$12&TEXT(B17," - ")&B17 -> Beta - 18 | T8: =MIN(DEGREES(ACOS((-TAN($B2*PI()/180))*TAN(E6*PI()/180))),DEGREES(ACOS((-TAN(($B2-$B17)*PI()/180))*TAN(E6*PI()/180)))) -> 64.357072 | U8: =MIN(DEGREES(ACOS((-TAN($B2*PI()/180))*TAN(F6*PI()/180))),DEGREES(ACOS((-TAN(($B2-$B17)*PI()/180))*TAN(F6*PI()/180)))) -> 74.902424 | V8: =MIN(DEGREES(ACOS((-TAN($B2*PI()/180))*TAN(G6*PI()/180))),DEGREES(ACOS((-TAN(($B2-$B17)*PI()/180))*TAN(G6*PI()/180)))) -> 87.259767 | W8: =MIN(DEGREES(ACOS((-TAN($B2*PI()/180))*TAN(H6*PI()/180))),DEGREES(ACOS((-TAN(($B2-$B17)*PI()/180))*TAN(H6*PI()/180)))) -> 95.616419 | X8: =MIN(DEGREES(ACOS((-TAN($B2*PI()/180))*TAN(I6*PI()/180))),DEGREES(ACOS((-TAN(($B2-$B17)*PI()/180))*TAN(I6*PI()/180)))) -> 101.58578 | Y8: =MIN(DEGREES(ACOS((-TAN($B2*PI()/180))*TAN(J6*PI()/180))),DEGREES(ACOS((-TAN(($B2-$B17)*PI()/180))*TAN(J6*PI()/180)))) -> 104.57097 | Z8: =MIN(DEGREES(ACOS((-TAN($B2*PI()/180))*TAN(K6*PI()/180))),DEGREES(ACOS((-TAN(($B2-$B17)*PI()/180))*TAN(K6*PI()/180)))) -> 103.22281 | AA8: =MIN(DEGREES(ACOS((-TAN($B2*PI()/180))*TAN(L6*PI()/180))),DEGREES(ACOS((-TAN(($B2-$B17)*PI()/180))*TAN(L6*PI()/180)))) -> 98.117807 | ... AE8: =MIN(DEGREES(ACOS((-TAN($B2*PI()/180))*TAN(P6*PI()/180))),DEGREES(ACOS((-TAN(($B2-$B17)*PI()/180))*TAN(P6*PI()/180)))) -> 61.198025
D9: KtBar | E9: =E3/E8 -> 0.52037248 | F9: =F3/F8 -> 0.5456971 | G9: =G3/G8 -> 0.55311751 | H9: =H3/H8 -> 0.5235038 | I9: =I3/I8 -> 0.47166954 | J9: =J3/J8 -> 0.47203087 | K9: =K3/K8 -> 0.44560533 | L9: =L3/L8 -> 0.46446491 | ... P9: =P3/P8 -> 0.46800218 | S9: =$A$12&TEXT(B18," - ")&B18 -> Beta - 21 | T9: =MIN(DEGREES(ACOS((-TAN($B2*PI()/180))*TAN(E6*PI()/180))),DEGREES(ACOS((-TAN(($B2-$B18)*PI()/180))*TAN(E6*PI()/180)))) -> 64.357072 | U9: =MIN(DEGREES(ACOS((-TAN($B2*PI()/180))*TAN(F6*PI()/180))),DEGREES(ACOS((-TAN(($B2-$B18)*PI()/180))*TAN(F6*PI()/180)))) -> 74.902424 | V9: =MIN(DEGREES(ACOS((-TAN($B2*PI()/180))*TAN(G6*PI()/180))),DEGREES(ACOS((-TAN(($B2-$B18)*PI()/180))*TAN(G6*PI()/180)))) -> 87.259767 | W9: =MIN(DEGREES(ACOS((-TAN($B2*PI()/180))*TAN(H6*PI()/180))),DEGREES(ACOS((-TAN(($B2-$B18)*PI()/180))*TAN(H6*PI()/180)))) -> 94.962421 | X9: =MIN(DEGREES(ACOS((-TAN($B2*PI()/180))*TAN(I6*PI()/180))),DEGREES(ACOS((-TAN(($B2-$B18)*PI()/180))*TAN(I6*PI()/180)))) -> 100.22482 | Y9: =MIN(DEGREES(ACOS((-TAN($B2*PI()/180))*TAN(J6*PI()/180))),DEGREES(ACOS((-TAN(($B2-$B18)*PI()/180))*TAN(J6*PI()/180)))) -> 102.84782 | Z9: =MIN(DEGREES(ACOS((-TAN($B2*PI()/180))*TAN(K6*PI()/180))),DEGREES(ACOS((-TAN(($B2-$B18)*PI()/180))*TAN(K6*PI()/180)))) -> 101.66413 | AA9: =MIN(DEGREES(ACOS((-TAN($B2*PI()/180))*TAN(L6*PI()/180))),DEGREES(ACOS((-TAN(($B2-$B18)*PI()/180))*TAN(L6*PI()/180)))) -> 97.169775 | ... AE9: =MIN(DEGREES(ACOS((-TAN($B2*PI()/180))*TAN(P6*PI()/180))),DEGREES(ACOS((-TAN(($B2-$B18)*PI()/180))*TAN(P6*PI()/180)))) -> 61.198025
D10: HdBar/Hbar | E10: =IF(E7<= 81.4,(1.391 - (3.56*E9) + (4.189*E9*E9) - (2.137*E9*E9*E9)),(1.311 - (3.022*E9) + (3.427*E9*E9) - (1.821*E9*E9*E9))) -> 0.37167742 | F10: =IF(F7<= 81.4,(1.391 - (3.56*F9) + (4.189*F9*F9) - (2.137*F9*F9*F9)),(1.311 - (3.022*F9) + (3.427*F9*F9) - (1.821*F9*F9*F9))) -> 0.3484773 | G10: =IF(G7<= 81.4,(1.391 - (3.56*G9) + (4.189*G9*G9) - (2.137*G9*G9*G9)),(1.311 - (3.022*G9) + (3.427*G9*G9) - (1.821*G9*G9*G9))) -> 0.37978177 | H10: =IF(H7<= 81.4,(1.391 - (3.56*H9) + (4.189*H9*H9) - (2.137*H9*H9*H9)),(1.311 - (3.022*H9) + (3.427*H9*H9) - (1.821*H9*H9*H9))) -> 0.4069043 | I10: =IF(I7<= 81.4,(1.391 - (3.56*I9) + (4.189*I9*I9) - (2.137*I9*I9*I9)),(1.311 - (3.022*I9) + (3.427*I9*I9) - (1.821*I9*I9*I9))) -> 0.45694311 | J10: =IF(J7<= 81.4,(1.391 - (3.56*J9) + (4.189*J9*J9) - (2.137*J9*J9*J9)),(1.311 - (3.022*J9) + (3.427*J9*J9) - (1.821*J9*J9*J9))) -> 0.45658025 | K10: =IF(K7<= 81.4,(1.391 - (3.56*K9) + (4.189*K9*K9) - (2.137*K9*K9*K9)),(1.311 - (3.022*K9) + (3.427*K9*K9) - (1.821*K9*K9*K9))) -> 0.48373558 | L10: =IF(L7<= 81.4,(1.391 - (3.56*L9) + (4.189*L9*L9) - (2.137*L9*L9*L9)),(1.311 - (3.022*L9) + (3.427*L9*L9) - (1.821*L9*L9*L9))) -> 0.46422529 | ... P10: =IF(P7<= 81.4,(1.391 - (3.56*P9) + (4.189*P9*P9) - (2.137*P9*P9*P9)),(1.311 - (3.022*P9) + (3.427*P9*P9) - (1.821*P9*P9*P9))) -> 0.42335986 | S10: =$A$12&TEXT(B19," - ")&B19 -> Beta - 24 | T10: =MIN(DEGREES(ACOS((-TAN($B2*PI()/180))*TAN(E6*PI()/180))),DEGREES(ACOS((-TAN(($B2-$B19)*PI()/180))*TAN(E6*PI()/180)))) -> 64.357072 | U10: =MIN(DEGREES(ACOS((-TAN($B2*PI()/180))*TAN(F6*PI()/180))),DEGREES(ACOS((-TAN(($B2-$B19)*PI()/180))*TAN(F6*PI()/180)))) -> 74.902424 | V10: =MIN(DEGREES(ACOS((-TAN($B2*PI()/180))*TAN(G6*PI()/180))),DEGREES(ACOS((-TAN(($B2-$B19)*PI()/180))*TAN(G6*PI()/180)))) -> 87.259767 | W10: =MIN(DEGREES(ACOS((-TAN($B2*PI()/180))*TAN(H6*PI()/180))),DEGREES(ACOS((-TAN(($B2-$B19)*PI()/180))*TAN(H6*PI()/180)))) -> 94.34383 | X10: =MIN(DEGREES(ACOS((-TAN($B2*PI()/180))*TAN(I6*PI()/180))),DEGREES(ACOS((-TAN(($B2-$B19)*PI()/180))*TAN(I6*PI()/180)))) -> 98.941672 | Y10: =MIN(DEGREES(ACOS((-TAN($B2*PI()/180))*TAN(J6*PI()/180))),DEGREES(ACOS((-TAN(($B2-$B19)*PI()/180))*TAN(J6*PI()/180)))) -> 101.22724 | Z10: =MIN(DEGREES(ACOS((-TAN($B2*PI()/180))*TAN(K6*PI()/180))),DEGREES(ACOS((-TAN(($B2-$B19)*PI()/180))*TAN(K6*PI()/180)))) -> 100.19646 | AA10: =MIN(DEGREES(ACOS((-TAN($B2*PI()/180))*TAN(L6*PI()/180))),DEGREES(ACOS((-TAN(($B2-$B19)*PI()/180))*TAN(L6*PI()/180)))) -> 96.274021 | ... AE10: =MIN(DEGREES(ACOS((-TAN($B2*PI()/180))*TAN(P6*PI()/180))),DEGREES(ACOS((-TAN(($B2-$B19)*PI()/180))*TAN(P6*PI()/180)))) -> 61.198025
D11: HdBar | E11: =E10*E3 -> 1.9267757 | F11: =F10*F3 -> 2.9481179 | G11: =G10*G3 -> 4.8809553 | H11: =H10*H3 -> 6.811578 | I11: =I10*I3 -> 8.3401257 | J11: =J10*J3 -> 8.9745414 | K11: =K10*K3 -> 8.654997 | L11: =L10*L3 -> 7.4536012 | ... P11: =P10*P3 -> 1.691746 | S11: =$A$12&TEXT(B20," - ")&B20 -> Beta - 27 | T11: =MIN(DEGREES(ACOS((-TAN($B2*PI()/180))*TAN(E6*PI()/180))),DEGREES(ACOS((-TAN(($B2-$B20)*PI()/180))*TAN(E6*PI()/180)))) -> 64.357072 | U11: =MIN(DEGREES(ACOS((-TAN($B2*PI()/180))*TAN(F6*PI()/180))),DEGREES(ACOS((-TAN(($B2-$B20)*PI()/180))*TAN(F6*PI()/180)))) -> 74.902424 | V11: =MIN(DEGREES(ACOS((-TAN($B2*PI()/180))*TAN(G6*PI()/180))),DEGREES(ACOS((-TAN(($B2-$B20)*PI()/180))*TAN(G6*PI()/180)))) -> 87.259767 | W11: =MIN(DEGREES(ACOS((-TAN($B2*PI()/180))*TAN(H6*PI()/180))),DEGREES(ACOS((-TAN(($B2-$B20)*PI()/180))*TAN(H6*PI()/180)))) -> 93.754636 | X11: =MIN(DEGREES(ACOS((-TAN($B2*PI()/180))*TAN(I6*PI()/180))),DEGREES(ACOS((-TAN(($B2-$B20)*PI()/180))*TAN(I6*PI()/180)))) -> 97.722723 | Y11: =MIN(DEGREES(ACOS((-TAN($B2*PI()/180))*TAN(J6*PI()/180))),DEGREES(ACOS((-TAN(($B2-$B20)*PI()/180))*TAN(J6*PI()/180)))) -> 99.690876 | Z11: =MIN(DEGREES(ACOS((-TAN($B2*PI()/180))*TAN(K6*PI()/180))),DEGREES(ACOS((-TAN(($B2-$B20)*PI()/180))*TAN(K6*PI()/180)))) -> 98.8037 | AA11: =MIN(DEGREES(ACOS((-TAN($B2*PI()/180))*TAN(L6*PI()/180))),DEGREES(ACOS((-TAN(($B2-$B20)*PI()/180))*TAN(L6*PI()/180)))) -> 95.421585 | ... AE11: =MIN(DEGREES(ACOS((-TAN($B2*PI()/180))*TAN(P6*PI()/180))),DEGREES(ACOS((-TAN(($B2-$B20)*PI()/180))*TAN(P6*PI()/180)))) -> 61.198025
A12: Beta | B12: 3 | D12: ="RbBar at Beta = "&B12 -> RbBar at Beta = 3 | E12: =(((COS(($B2-$B12)*PI()/180)*COS(E6*PI()/180)*SIN(T3*PI()/180))+((PI()/180)*T3*SIN(($B2-$B12)*PI()/180)*SIN(E6*PI()/180)))/((COS($B2*PI()/180)*COS(E6*PI()/180)*SIN(E7*PI()/180))+((PI()/180)*E7*SIN($B2*PI()/180)*SIN(E6*PI()/180)))) -> 1.1813173 | F12: =(((COS(($B2-$B12)*PI()/180)*COS(F6*PI()/180)*SIN(U3*PI()/180))+((PI()/180)*U3*SIN(($B2-$B12)*PI()/180)*SIN(F6*PI()/180)))/((COS($B2*PI()/180)*COS(F6*PI()/180)*SIN(F7*PI()/180))+((PI()/180)*F7*SIN($B2*PI()/180)*SIN(F6*PI()/180)))) -> 1.1153568 | G12: =(((COS(($B2-$B12)*PI()/180)*COS(G6*PI()/180)*SIN(V3*PI()/180))+((PI()/180)*V3*SIN(($B2-$B12)*PI()/180)*SIN(G6*PI()/180)))/((COS($B2*PI()/180)*COS(G6*PI()/180)*SIN(G7*PI()/180))+((PI()/180)*G7*SIN($B2*PI()/180)*SIN(G6*PI()/180)))) -> 1.0661821 | H12: =(((COS(($B2-$B12)*PI()/180)*COS(H6*PI()/180)*SIN(W3*PI()/180))+((PI()/180)*W3*SIN(($B2-$B12)*PI()/180)*SIN(H6*PI()/180)))/((COS($B2*PI()/180)*COS(H6*PI()/180)*SIN(H7*PI()/180))+((PI()/180)*H7*SIN($B2*PI()/180)*SIN(H6*PI()/180)))) -> 1.0314829 | I12: =(((COS(($B2-$B12)*PI()/180)*COS(I6*PI()/180)*SIN(X3*PI()/180))+((PI()/180)*X3*SIN(($B2-$B12)*PI()/180)*SIN(I6*PI()/180)))/((COS($B2*PI()/180)*COS(I6*PI()/180)*SIN(I7*PI()/180))+((PI()/180)*I7*SIN($B2*PI()/180)*SIN(I6*PI()/180)))) -> 1.0108343 | J12: =(((COS(($B2-$B12)*PI()/180)*COS(J6*PI()/180)*SIN(Y3*PI()/180))+((PI()/180)*Y3*SIN(($B2-$B12)*PI()/180)*SIN(J6*PI()/180)))/((COS($B2*PI()/180)*COS(J6*PI()/180)*SIN(J7*PI()/180))+((PI()/180)*J7*SIN($B2*PI()/180)*SIN(J6*PI()/180)))) -> 1.0023636 | K12: =(((COS(($B2-$B12)*PI()/180)*COS(K6*PI()/180)*SIN(Z3*PI()/180))+((PI()/180)*Z3*SIN(($B2-$B12)*PI()/180)*SIN(K6*PI()/180)))/((COS($B2*PI()/180)*COS(K6*PI()/180)*SIN(K7*PI()/180))+((PI()/180)*K7*SIN($B2*PI()/180)*SIN(K6*PI()/180)))) -> 1.0060677 | L12: =(((COS(($B2-$B12)*PI()/180)*COS(L6*PI()/180)*SIN(AA3*PI()/180))+((PI()/180)*AA3*SIN(($B2-$B12)*PI()/180)*SIN(L6*PI()/180)))/((COS($B2*PI()/180)*COS(L6*PI()/180)*SIN(L7*PI()/180))+((PI()/180)*L7*SIN($B2*PI()/180)*SIN(L6*PI()/180)))) -> 1.0221108 | ... P12: =(((COS(($B2-$B12)*PI()/180)*COS(P6*PI()/180)*SIN(AE3*PI()/180))+((PI()/180)*AE3*SIN(($B2-$B12)*PI()/180)*SIN(P6*PI()/180)))/((COS($B2*PI()/180)*COS(P6*PI()/180)*SIN(P7*PI()/180))+((PI()/180)*P7*SIN($B2*PI()/180)*SIN(P6*PI()/180)))) -> 1.2079607 | S12: =$A$12&TEXT(B21," - ")&B21 -> Beta - 30 | T12: =MIN(DEGREES(ACOS((-TAN($B2*PI()/180))*TAN(E6*PI()/180))),DEGREES(ACOS((-TAN(($B2-$B21)*PI()/180))*TAN(E6*PI()/180)))) -> 64.357072 | U12: =MIN(DEGREES(ACOS((-TAN($B2*PI()/180))*TAN(F6*PI()/180))),DEGREES(ACOS((-TAN(($B2-$B21)*PI()/180))*TAN(F6*PI()/180)))) -> 74.902424 | V12: =MIN(DEGREES(ACOS((-TAN($B2*PI()/180))*TAN(G6*PI()/180))),DEGREES(ACOS((-TAN(($B2-$B21)*PI()/180))*TAN(G6*PI()/180)))) -> 87.259767 | W12: =MIN(DEGREES(ACOS((-TAN($B2*PI()/180))*TAN(H6*PI()/180))),DEGREES(ACOS((-TAN(($B2-$B21)*PI()/180))*TAN(H6*PI()/180)))) -> 93.189711 | X12: =MIN(DEGREES(ACOS((-TAN($B2*PI()/180))*TAN(I6*PI()/180))),DEGREES(ACOS((-TAN(($B2-$B21)*PI()/180))*TAN(I6*PI()/180)))) -> 96.556513 | Y12: =MIN(DEGREES(ACOS((-TAN($B2*PI()/180))*TAN(J6*PI()/180))),DEGREES(ACOS((-TAN(($B2-$B21)*PI()/180))*TAN(J6*PI()/180)))) -> 98.22342 | Z12: =MIN(DEGREES(ACOS((-TAN($B2*PI()/180))*TAN(K6*PI()/180))),DEGREES(ACOS((-TAN(($B2-$B21)*PI()/180))*TAN(K6*PI()/180)))) -> 97.472343 | AA12: =MIN(DEGREES(ACOS((-TAN($B2*PI()/180))*TAN(L6*PI()/180))),DEGREES(ACOS((-TAN(($B2-$B21)*PI()/180))*TAN(L6*PI()/180)))) -> 94.604851 | ... AE12: =MIN(DEGREES(ACOS((-TAN($B2*PI()/180))*TAN(P6*PI()/180))),DEGREES(ACOS((-TAN(($B2-$B21)*PI()/180))*TAN(P6*PI()/180)))) -> 61.198025
B13: =B12+3 -> 6 | D13: ="RbBar at Beta = "&B13 -> RbBar at Beta = 6 | E13: =(((COS(($B2-$B13)*PI()/180)*COS(E6*PI()/180)*SIN(T4*PI()/180))+((PI()/180)*T4*SIN(($B2-$B13)*PI()/180)*SIN(E6*PI()/180)))/((COS($B2*PI()/180)*COS(E6*PI()/180)*SIN(E7*PI()/180))+((PI()/180)*E7*SIN($B2*PI()/180)*SIN(E6*PI()/180)))) -> 1.3593966 | F13: =(((COS(($B2-$B13)*PI()/180)*COS(F6*PI()/180)*SIN(U4*PI()/180))+((PI()/180)*U4*SIN(($B2-$B13)*PI()/180)*SIN(F6*PI()/180)))/((COS($B2*PI()/180)*COS(F6*PI()/180)*SIN(F7*PI()/180))+((PI()/180)*F7*SIN($B2*PI()/180)*SIN(F6*PI()/180)))) -> 1.2276564 | G13: =(((COS(($B2-$B13)*PI()/180)*COS(G6*PI()/180)*SIN(V4*PI()/180))+((PI()/180)*V4*SIN(($B2-$B13)*PI()/180)*SIN(G6*PI()/180)))/((COS($B2*PI()/180)*COS(G6*PI()/180)*SIN(G7*PI()/180))+((PI()/180)*G7*SIN($B2*PI()/180)*SIN(G6*PI()/180)))) -> 1.1294418 | H13: =(((COS(($B2-$B13)*PI()/180)*COS(H6*PI()/180)*SIN(W4*PI()/180))+((PI()/180)*W4*SIN(($B2-$B13)*PI()/180)*SIN(H6*PI()/180)))/((COS($B2*PI()/180)*COS(H6*PI()/180)*SIN(H7*PI()/180))+((PI()/180)*H7*SIN($B2*PI()/180)*SIN(H6*PI()/180)))) -> 1.0603958 | I13: =(((COS(($B2-$B13)*PI()/180)*COS(I6*PI()/180)*SIN(X4*PI()/180))+((PI()/180)*X4*SIN(($B2-$B13)*PI()/180)*SIN(I6*PI()/180)))/((COS($B2*PI()/180)*COS(I6*PI()/180)*SIN(I7*PI()/180))+((PI()/180)*I7*SIN($B2*PI()/180)*SIN(I6*PI()/180)))) -> 1.0197875 | J13: =(((COS(($B2-$B13)*PI()/180)*COS(J6*PI()/180)*SIN(Y4*PI()/180))+((PI()/180)*Y4*SIN(($B2-$B13)*PI()/180)*SIN(J6*PI()/180)))/((COS($B2*PI()/180)*COS(J6*PI()/180)*SIN(J7*PI()/180))+((PI()/180)*J7*SIN($B2*PI()/180)*SIN(J6*PI()/180)))) -> 1.0032817 | K13: =(((COS(($B2-$B13)*PI()/180)*COS(K6*PI()/180)*SIN(Z4*PI()/180))+((PI()/180)*Z4*SIN(($B2-$B13)*PI()/180)*SIN(K6*PI()/180)))/((COS($B2*PI()/180)*COS(K6*PI()/180)*SIN(K7*PI()/180))+((PI()/180)*K7*SIN($B2*PI()/180)*SIN(K6*PI()/180)))) -> 1.0104857 | L13: =(((COS(($B2-$B13)*PI()/180)*COS(L6*PI()/180)*SIN(AA4*PI()/180))+((PI()/180)*AA4*SIN(($B2-$B13)*PI()/180)*SIN(L6*PI()/180)))/((COS($B2*PI()/180)*COS(L6*PI()/180)*SIN(L7*PI()/180))+((PI()/180)*L7*SIN($B2*PI()/180)*SIN(L6*PI()/180)))) -> 1.0419085 | ... P13: =(((COS(($B2-$B13)*PI()/180)*COS(P6*PI()/180)*SIN(AE4*PI()/180))+((PI()/180)*AE4*SIN(($B2-$B13)*PI()/180)*SIN(P6*PI()/180)))/((COS($B2*PI()/180)*COS(P6*PI()/180)*SIN(P7*PI()/180))+((PI()/180)*P7*SIN($B2*PI()/180)*SIN(P6*PI()/180)))) -> 1.4126105 | S13: =$A$12&TEXT(B22," - ")&B22 -> Beta - 33 | T13: =MIN(DEGREES(ACOS((-TAN($B2*PI()/180))*TAN(E6*PI()/180))),DEGREES(ACOS((-TAN(($B2-$B22)*PI()/180))*TAN(E6*PI()/180)))) -> 64.357072 | U13: =MIN(DEGREES(ACOS((-TAN($B2*PI()/180))*TAN(F6*PI()/180))),DEGREES(ACOS((-TAN(($B2-$B22)*PI()/180))*TAN(F6*PI()/180)))) -> 74.902424 | V13: =MIN(DEGREES(ACOS((-TAN($B2*PI()/180))*TAN(G6*PI()/180))),DEGREES(ACOS((-TAN(($B2-$B22)*PI()/180))*TAN(G6*PI()/180)))) -> 87.259767 | W13: =MIN(DEGREES(ACOS((-TAN($B2*PI()/180))*TAN(H6*PI()/180))),DEGREES(ACOS((-TAN(($B2-$B22)*PI()/180))*TAN(H6*PI()/180)))) -> 92.644607 | X13: =MIN(DEGREES(ACOS((-TAN($B2*PI()/180))*TAN(I6*PI()/180))),DEGREES(ACOS((-TAN(($B2-$B22)*PI()/180))*TAN(I6*PI()/180)))) -> 95.4332 | Y13: =MIN(DEGREES(ACOS((-TAN($B2*PI()/180))*TAN(J6*PI()/180))),DEGREES(ACOS((-TAN(($B2-$B22)*PI()/180))*TAN(J6*PI()/180)))) -> 96.811832 | Z13: =MIN(DEGREES(ACOS((-TAN($B2*PI()/180))*TAN(K6*PI()/180))),DEGREES(ACOS((-TAN(($B2-$B22)*PI()/180))*TAN(K6*PI()/180)))) -> 96.190851 | AA13: =MIN(DEGREES(ACOS((-TAN($B2*PI()/180))*TAN(L6*PI()/180))),DEGREES(ACOS((-TAN(($B2-$B22)*PI()/180))*TAN(L6*PI()/180)))) -> 93.817238 | ... AE13: =MIN(DEGREES(ACOS((-TAN($B2*PI()/180))*TAN(P6*PI()/180))),DEGREES(ACOS((-TAN(($B2-$B22)*PI()/180))*TAN(P6*PI()/180)))) -> 61.198025
B14: =B13+3 -> 9 | D14: ="RbBar at Beta = "&B14 -> RbBar at Beta = 9 | E14: =(((COS(($B2-$B14)*PI()/180)*COS(E6*PI()/180)*SIN(T5*PI()/180))+((PI()/180)*T5*SIN(($B2-$B14)*PI()/180)*SIN(E6*PI()/180)))/((COS($B2*PI()/180)*COS(E6*PI()/180)*SIN(E7*PI()/180))+((PI()/180)*E7*SIN($B2*PI()/180)*SIN(E6*PI()/180)))) -> 1.53375 | F14: =(((COS(($B2-$B14)*PI()/180)*COS(F6*PI()/180)*SIN(U5*PI()/180))+((PI()/180)*U5*SIN(($B2-$B14)*PI()/180)*SIN(F6*PI()/180)))/((COS($B2*PI()/180)*COS(F6*PI()/180)*SIN(F7*PI()/180))+((PI()/180)*F7*SIN($B2*PI()/180)*SIN(F6*PI()/180)))) -> 1.3365912 | G14: =(((COS(($B2-$B14)*PI()/180)*COS(G6*PI()/180)*SIN(V5*PI()/180))+((PI()/180)*V5*SIN(($B2-$B14)*PI()/180)*SIN(G6*PI()/180)))/((COS($B2*PI()/180)*COS(G6*PI()/180)*SIN(G7*PI()/180))+((PI()/180)*G7*SIN($B2*PI()/180)*SIN(G6*PI()/180)))) -> 1.1896058 | H14: =(((COS(($B2-$B14)*PI()/180)*COS(H6*PI()/180)*SIN(W5*PI()/180))+((PI()/180)*W5*SIN(($B2-$B14)*PI()/180)*SIN(H6*PI()/180)))/((COS($B2*PI()/180)*COS(H6*PI()/180)*SIN(H7*PI()/180))+((PI()/180)*H7*SIN($B2*PI()/180)*SIN(H6*PI()/180)))) -> 1.0866224 | I14: =(((COS(($B2-$B14)*PI()/180)*COS(I6*PI()/180)*SIN(X5*PI()/180))+((PI()/180)*X5*SIN(($B2-$B14)*PI()/180)*SIN(I6*PI()/180)))/((COS($B2*PI()/180)*COS(I6*PI()/180)*SIN(I7*PI()/180))+((PI()/180)*I7*SIN($B2*PI()/180)*SIN(I6*PI()/180)))) -> 1.0266993 | J14: =(((COS(($B2-$B14)*PI()/180)*COS(J6*PI()/180)*SIN(Y5*PI()/180))+((PI()/180)*Y5*SIN(($B2-$B14)*PI()/180)*SIN(J6*PI()/180)))/((COS($B2*PI()/180)*COS(J6*PI()/180)*SIN(J7*PI()/180))+((PI()/180)*J7*SIN($B2*PI()/180)*SIN(J6*PI()/180)))) -> 1.0025435 | K14: =(((COS(($B2-$B14)*PI()/180)*COS(K6*PI()/180)*SIN(Z5*PI()/180))+((PI()/180)*Z5*SIN(($B2-$B14)*PI()/180)*SIN(K6*PI()/180)))/((COS($B2*PI()/180)*COS(K6*PI()/180)*SIN(K7*PI()/180))+((PI()/180)*K7*SIN($B2*PI()/180)*SIN(K6*PI()/180)))) -> 1.0130687 | L14: =(((COS(($B2-$B14)*PI()/180)*COS(L6*PI()/180)*SIN(AA5*PI()/180))+((PI()/180)*AA5*SIN(($B2-$B14)*PI()/180)*SIN(L6*PI()/180)))/((COS($B2*PI()/180)*COS(L6*PI()/180)*SIN(L7*PI()/180))+((PI()/180)*L7*SIN($B2*PI()/180)*SIN(L6*PI()/180)))) -> 1.0592673 | ... P14: =(((COS(($B2-$B14)*PI()/180)*COS(P6*PI()/180)*SIN(AE5*PI()/180))+((PI()/180)*AE5*SIN(($B2-$B14)*PI()/180)*SIN(P6*PI()/180)))/((COS($B2*PI()/180)*COS(P6*PI()/180)*SIN(P7*PI()/180))+((PI()/180)*P7*SIN($B2*PI()/180)*SIN(P6*PI()/180)))) -> 1.6133884 | S14: =$A$12&TEXT(B23," - ")&B23 -> Beta - 36 | T14: =MIN(DEGREES(ACOS((-TAN($B2*PI()/180))*TAN(E6*PI()/180))),DEGREES(ACOS((-TAN(($B2-$B23)*PI()/180))*TAN(E6*PI()/180)))) -> 64.357072 | U14: =MIN(DEGREES(ACOS((-TAN($B2*PI()/180))*TAN(F6*PI()/180))),DEGREES(ACOS((-TAN(($B2-$B23)*PI()/180))*TAN(F6*PI()/180)))) -> 74.902424 | V14: =MIN(DEGREES(ACOS((-TAN($B2*PI()/180))*TAN(G6*PI()/180))),DEGREES(ACOS((-TAN(($B2-$B23)*PI()/180))*TAN(G6*PI()/180)))) -> 87.259767 | W14: =MIN(DEGREES(ACOS((-TAN($B2*PI()/180))*TAN(H6*PI()/180))),DEGREES(ACOS((-TAN(($B2-$B23)*PI()/180))*TAN(H6*PI()/180)))) -> 92.115403 | X14: =MIN(DEGREES(ACOS((-TAN($B2*PI()/180))*TAN(I6*PI()/180))),DEGREES(ACOS((-TAN(($B2-$B23)*PI()/180))*TAN(I6*PI()/180)))) -> 94.344186 | Y14: =MIN(DEGREES(ACOS((-TAN($B2*PI()/180))*TAN(J6*PI()/180))),DEGREES(ACOS((-TAN(($B2-$B23)*PI()/180))*TAN(J6*PI()/180)))) -> 95.444798 | Z14: =MIN(DEGREES(ACOS((-TAN($B2*PI()/180))*TAN(K6*PI()/180))),DEGREES(ACOS((-TAN(($B2-$B23)*PI()/180))*TAN(K6*PI()/180)))) -> 94.949174 | AA14: =MIN(DEGREES(ACOS((-TAN($B2*PI()/180))*TAN(L6*PI()/180))),DEGREES(ACOS((-TAN(($B2-$B23)*PI()/180))*TAN(L6*PI()/180)))) -> 93.052959 | ... AE14: =MIN(DEGREES(ACOS((-TAN($B2*PI()/180))*TAN(P6*PI()/180))),DEGREES(ACOS((-TAN(($B2-$B23)*PI()/180))*TAN(P6*PI()/180)))) -> 61.198025
B15: =B14+3 -> 12 | D15: ="RbBar at Beta = "&B15 -> RbBar at Beta = 12 | E15: =(((COS(($B2-$B15)*PI()/180)*COS(E6*PI()/180)*SIN(T6*PI()/180))+((PI()/180)*T6*SIN(($B2-$B15)*PI()/180)*SIN(E6*PI()/180)))/((COS($B2*PI()/180)*COS(E6*PI()/180)*SIN(E7*PI()/180))+((PI()/180)*E7*SIN($B2*PI()/180)*SIN(E6*PI()/180)))) -> 1.7038994 | F15: =(((COS(($B2-$B15)*PI()/180)*COS(F6*PI()/180)*SIN(U6*PI()/180))+((PI()/180)*U6*SIN(($B2-$B15)*PI()/180)*SIN(F6*PI()/180)))/((COS($B2*PI()/180)*COS(F6*PI()/180)*SIN(F7*PI()/180))+((PI()/180)*F7*SIN($B2*PI()/180)*SIN(F6*PI()/180)))) -> 1.4418624 | G15: =(((COS(($B2-$B15)*PI()/180)*COS(G6*PI()/180)*SIN(V6*PI()/180))+((PI()/180)*V6*SIN(($B2-$B15)*PI()/180)*SIN(G6*PI()/180)))/((COS($B2*PI()/180)*COS(G6*PI()/180)*SIN(G7*PI()/180))+((PI()/180)*G7*SIN($B2*PI()/180)*SIN(G6*PI()/180)))) -> 1.2465092 | H15: =(((COS(($B2-$B15)*PI()/180)*COS(H6*PI()/180)*SIN(W6*PI()/180))+((PI()/180)*W6*SIN(($B2-$B15)*PI()/180)*SIN(H6*PI()/180)))/((COS($B2*PI()/180)*COS(H6*PI()/180)*SIN(H7*PI()/180))+((PI()/180)*H7*SIN($B2*PI()/180)*SIN(H6*PI()/180)))) -> 1.1100621 | I15: =(((COS(($B2-$B15)*PI()/180)*COS(I6*PI()/180)*SIN(X6*PI()/180))+((PI()/180)*X6*SIN(($B2-$B15)*PI()/180)*SIN(I6*PI()/180)))/((COS($B2*PI()/180)*COS(I6*PI()/180)*SIN(I7*PI()/180))+((PI()/180)*I7*SIN($B2*PI()/180)*SIN(I6*PI()/180)))) -> 1.0314474 | J15: =(((COS(($B2-$B15)*PI()/180)*COS(J6*PI()/180)*SIN(Y6*PI()/180))+((PI()/180)*Y6*SIN(($B2-$B15)*PI()/180)*SIN(J6*PI()/180)))/((COS($B2*PI()/180)*COS(J6*PI()/180)*SIN(J7*PI()/180))+((PI()/180)*J7*SIN($B2*PI()/180)*SIN(J6*PI()/180)))) -> 0.99999431 | K15: =(((COS(($B2-$B15)*PI()/180)*COS(K6*PI()/180)*SIN(Z6*PI()/180))+((PI()/180)*Z6*SIN(($B2-$B15)*PI()/180)*SIN(K6*PI()/180)))/((COS($B2*PI()/180)*COS(K6*PI()/180)*SIN(K7*PI()/180))+((PI()/180)*K7*SIN($B2*PI()/180)*SIN(K6*PI()/180)))) -> 1.0136786 | L15: =(((COS(($B2-$B15)*PI()/180)*COS(L6*PI()/180)*SIN(AA6*PI()/180))+((PI()/180)*AA6*SIN(($B2-$B15)*PI()/180)*SIN(L6*PI()/180)))/((COS($B2*PI()/180)*COS(L6*PI()/180)*SIN(L7*PI()/180))+((PI()/180)*L7*SIN($B2*PI()/180)*SIN(L6*PI()/180)))) -> 1.0740843 | ... P15: =(((COS(($B2-$B15)*PI()/180)*COS(P6*PI()/180)*SIN(AE6*PI()/180))+((PI()/180)*AE6*SIN(($B2-$B15)*PI()/180)*SIN(P6*PI()/180)))/((COS($B2*PI()/180)*COS(P6*PI()/180)*SIN(P7*PI()/180))+((PI()/180)*P7*SIN($B2*PI()/180)*SIN(P6*PI()/180)))) -> 1.8097441 | S15: =$A$12&TEXT(B24," - ")&B24 -> Beta - 39 | T15: =MIN(DEGREES(ACOS((-TAN($B2*PI()/180))*TAN(E6*PI()/180))),DEGREES(ACOS((-TAN(($B2-$B24)*PI()/180))*TAN(E6*PI()/180)))) -> 64.357072 | U15: =MIN(DEGREES(ACOS((-TAN($B2*PI()/180))*TAN(F6*PI()/180))),DEGREES(ACOS((-TAN(($B2-$B24)*PI()/180))*TAN(F6*PI()/180)))) -> 74.902424 | V15: =MIN(DEGREES(ACOS((-TAN($B2*PI()/180))*TAN(G6*PI()/180))),DEGREES(ACOS((-TAN(($B2-$B24)*PI()/180))*TAN(G6*PI()/180)))) -> 87.259767 | W15: =MIN(DEGREES(ACOS((-TAN($B2*PI()/180))*TAN(H6*PI()/180))),DEGREES(ACOS((-TAN(($B2-$B24)*PI()/180))*TAN(H6*PI()/180)))) -> 91.59858 | X15: =MIN(DEGREES(ACOS((-TAN($B2*PI()/180))*TAN(I6*PI()/180))),DEGREES(ACOS((-TAN(($B2-$B24)*PI()/180))*TAN(I6*PI()/180)))) -> 93.281808 | Y15: =MIN(DEGREES(ACOS((-TAN($B2*PI()/180))*TAN(J6*PI()/180))),DEGREES(ACOS((-TAN(($B2-$B24)*PI()/180))*TAN(J6*PI()/180)))) -> 94.112295 | Z15: =MIN(DEGREES(ACOS((-TAN($B2*PI()/180))*TAN(K6*PI()/180))),DEGREES(ACOS((-TAN(($B2-$B24)*PI()/180))*TAN(K6*PI()/180)))) -> 93.738386 | AA15: =MIN(DEGREES(ACOS((-TAN($B2*PI()/180))*TAN(L6*PI()/180))),DEGREES(ACOS((-TAN(($B2-$B24)*PI()/180))*TAN(L6*PI()/180)))) -> 92.306833 | ... AE15: =MIN(DEGREES(ACOS((-TAN($B2*PI()/180))*TAN(P6*PI()/180))),DEGREES(ACOS((-TAN(($B2-$B24)*PI()/180))*TAN(P6*PI()/180)))) -> 61.198025
B16: =B15+3 -> 15 | D16: ="RbBar at Beta = "&B16 -> RbBar at Beta = 15 | E16: =(((COS(($B2-$B16)*PI()/180)*COS(E6*PI()/180)*SIN(T7*PI()/180))+((PI()/180)*T7*SIN(($B2-$B16)*PI()/180)*SIN(E6*PI()/180)))/((COS($B2*PI()/180)*COS(E6*PI()/180)*SIN(E7*PI()/180))+((PI()/180)*E7*SIN($B2*PI()/180)*SIN(E6*PI()/180)))) -> 1.8693786 | F16: =(((COS(($B2-$B16)*PI()/180)*COS(F6*PI()/180)*SIN(U7*PI()/180))+((PI()/180)*U7*SIN(($B2-$B16)*PI()/180)*SIN(F6*PI()/180)))/((COS($B2*PI()/180)*COS(F6*PI()/180)*SIN(F7*PI()/180))+((PI()/180)*F7*SIN($B2*PI()/180)*SIN(F6*PI()/180)))) -> 1.5431816 | G16: =(((COS(($B2-$B16)*PI()/180)*COS(G6*PI()/180)*SIN(V7*PI()/180))+((PI()/180)*V7*SIN(($B2-$B16)*PI()/180)*SIN(G6*PI()/180)))/((COS($B2*PI()/180)*COS(G6*PI()/180)*SIN(G7*PI()/180))+((PI()/180)*G7*SIN($B2*PI()/180)*SIN(G6*PI()/180)))) -> 1.299996 | H16: =(((COS(($B2-$B16)*PI()/180)*COS(H6*PI()/180)*SIN(W7*PI()/180))+((PI()/180)*W7*SIN(($B2-$B16)*PI()/180)*SIN(H6*PI()/180)))/((COS($B2*PI()/180)*COS(H6*PI()/180)*SIN(H7*PI()/180))+((PI()/180)*H7*SIN($B2*PI()/180)*SIN(H6*PI()/180)))) -> 1.1306281 | I16: =(((COS(($B2-$B16)*PI()/180)*COS(I6*PI()/180)*SIN(X7*PI()/180))+((PI()/180)*X7*SIN(($B2-$B16)*PI()/180)*SIN(I6*PI()/180)))/((COS($B2*PI()/180)*COS(I6*PI()/180)*SIN(I7*PI()/180))+((PI()/180)*I7*SIN($B2*PI()/180)*SIN(I6*PI()/180)))) -> 1.0339384 | J16: =(((COS(($B2-$B16)*PI()/180)*COS(J6*PI()/180)*SIN(Y7*PI()/180))+((PI()/180)*Y7*SIN(($B2-$B16)*PI()/180)*SIN(J6*PI()/180)))/((COS($B2*PI()/180)*COS(J6*PI()/180)*SIN(J7*PI()/180))+((PI()/180)*J7*SIN($B2*PI()/180)*SIN(J6*PI()/180)))) -> 0.99552122 | K16: =(((COS(($B2-$B16)*PI()/180)*COS(K6*PI()/180)*SIN(Z7*PI()/180))+((PI()/180)*Z7*SIN(($B2-$B16)*PI()/180)*SIN(K6*PI()/180)))/((COS($B2*PI()/180)*COS(K6*PI()/180)*SIN(K7*PI()/180))+((PI()/180)*K7*SIN($B2*PI()/180)*SIN(K6*PI()/180)))) -> 1.0122126 | L16: =(((COS(($B2-$B16)*PI()/180)*COS(L6*PI()/180)*SIN(AA7*PI()/180))+((PI()/180)*AA7*SIN(($B2-$B16)*PI()/180)*SIN(L6*PI()/180)))/((COS($B2*PI()/180)*COS(L6*PI()/180)*SIN(L7*PI()/180))+((PI()/180)*L7*SIN($B2*PI()/180)*SIN(L6*PI()/180)))) -> 1.0862757 | ... P16: =(((COS(($B2-$B16)*PI()/180)*COS(P6*PI()/180)*SIN(AE7*PI()/180))+((PI()/180)*AE7*SIN(($B2-$B16)*PI()/180)*SIN(P6*PI()/180)))/((COS($B2*PI()/180)*COS(P6*PI()/180)*SIN(P7*PI()/180))+((PI()/180)*P7*SIN($B2*PI()/180)*SIN(P6*PI()/180)))) -> 2.0011395 | S16: =$A$12&TEXT(B25," - ")&B25 -> Beta - 42 | T16: =MIN(DEGREES(ACOS((-TAN($B2*PI()/180))*TAN(E6*PI()/180))),DEGREES(ACOS((-TAN(($B2-$B25)*PI()/180))*TAN(E6*PI()/180)))) -> 64.357072 | U16: =MIN(DEGREES(ACOS((-TAN($B2*PI()/180))*TAN(F6*PI()/180))),DEGREES(ACOS((-TAN(($B2-$B25)*PI()/180))*TAN(F6*PI()/180)))) -> 74.902424 | V16: =MIN(DEGREES(ACOS((-TAN($B2*PI()/180))*TAN(G6*PI()/180))),DEGREES(ACOS((-TAN(($B2-$B25)*PI()/180))*TAN(G6*PI()/180)))) -> 87.259767 | W16: =MIN(DEGREES(ACOS((-TAN($B2*PI()/180))*TAN(H6*PI()/180))),DEGREES(ACOS((-TAN(($B2-$B25)*PI()/180))*TAN(H6*PI()/180)))) -> 91.090917 | X16: =MIN(DEGREES(ACOS((-TAN($B2*PI()/180))*TAN(I6*PI()/180))),DEGREES(ACOS((-TAN(($B2-$B25)*PI()/180))*TAN(I6*PI()/180)))) -> 92.239101 | Y16: =MIN(DEGREES(ACOS((-TAN($B2*PI()/180))*TAN(J6*PI()/180))),DEGREES(ACOS((-TAN(($B2-$B25)*PI()/180))*TAN(J6*PI()/180)))) -> 92.805255 | Z16: =MIN(DEGREES(ACOS((-TAN($B2*PI()/180))*TAN(K6*PI()/180))),DEGREES(ACOS((-TAN(($B2-$B25)*PI()/180))*TAN(K6*PI()/180)))) -> 92.550392 | AA16: =MIN(DEGREES(ACOS((-TAN($B2*PI()/180))*TAN(L6*PI()/180))),DEGREES(ACOS((-TAN(($B2-$B25)*PI()/180))*TAN(L6*PI()/180)))) -> 91.574132 | ... AE16: =MIN(DEGREES(ACOS((-TAN($B2*PI()/180))*TAN(P6*PI()/180))),DEGREES(ACOS((-TAN(($B2-$B25)*PI()/180))*TAN(P6*PI()/180)))) -> 61.198025
B17: =B16+3 -> 18 | D17: ="RbBar at Beta = "&B17 -> RbBar at Beta = 18 | E17: =(((COS(($B2-$B17)*PI()/180)*COS(E6*PI()/180)*SIN(T8*PI()/180))+((PI()/180)*T8*SIN(($B2-$B17)*PI()/180)*SIN(E6*PI()/180)))/((COS($B2*PI()/180)*COS(E6*PI()/180)*SIN(E7*PI()/180))+((PI()/180)*E7*SIN($B2*PI()/180)*SIN(E6*PI()/180)))) -> 2.0297339 | F17: =(((COS(($B2-$B17)*PI()/180)*COS(F6*PI()/180)*SIN(U8*PI()/180))+((PI()/180)*U8*SIN(($B2-$B17)*PI()/180)*SIN(F6*PI()/180)))/((COS($B2*PI()/180)*COS(F6*PI()/180)*SIN(F7*PI()/180))+((PI()/180)*F7*SIN($B2*PI()/180)*SIN(F6*PI()/180)))) -> 1.640271 | G17: =(((COS(($B2-$B17)*PI()/180)*COS(G6*PI()/180)*SIN(V8*PI()/180))+((PI()/180)*V8*SIN(($B2-$B17)*PI()/180)*SIN(G6*PI()/180)))/((COS($B2*PI()/180)*COS(G6*PI()/180)*SIN(G7*PI()/180))+((PI()/180)*G7*SIN($B2*PI()/180)*SIN(G6*PI()/180)))) -> 1.3499196 | H17: =(((COS(($B2-$B17)*PI()/180)*COS(H6*PI()/180)*SIN(W8*PI()/180))+((PI()/180)*W8*SIN(($B2-$B17)*PI()/180)*SIN(H6*PI()/180)))/((COS($B2*PI()/180)*COS(H6*PI()/180)*SIN(H7*PI()/180))+((PI()/180)*H7*SIN($B2*PI()/180)*SIN(H6*PI()/180)))) -> 1.1482463 | I17: =(((COS(($B2-$B17)*PI()/180)*COS(I6*PI()/180)*SIN(X8*PI()/180))+((PI()/180)*X8*SIN(($B2-$B17)*PI()/180)*SIN(I6*PI()/180)))/((COS($B2*PI()/180)*COS(I6*PI()/180)*SIN(I7*PI()/180))+((PI()/180)*I7*SIN($B2*PI()/180)*SIN(I6*PI()/180)))) -> 1.0341025 | J17: =(((COS(($B2-$B17)*PI()/180)*COS(J6*PI()/180)*SIN(Y8*PI()/180))+((PI()/180)*Y8*SIN(($B2-$B17)*PI()/180)*SIN(J6*PI()/180)))/((COS($B2*PI()/180)*COS(J6*PI()/180)*SIN(J7*PI()/180))+((PI()/180)*J7*SIN($B2*PI()/180)*SIN(J6*PI()/180)))) -> 0.98904292 | K17: =(((COS(($B2-$B17)*PI()/180)*COS(K6*PI()/180)*SIN(Z8*PI()/180))+((PI()/180)*Z8*SIN(($B2-$B17)*PI()/180)*SIN(K6*PI()/180)))/((COS($B2*PI()/180)*COS(K6*PI()/180)*SIN(K7*PI()/180))+((PI()/180)*K7*SIN($B2*PI()/180)*SIN(K6*PI()/180)))) -> 1.0085956 | L17: =(((COS(($B2-$B17)*PI()/180)*COS(L6*PI()/180)*SIN(AA8*PI()/180))+((PI()/180)*AA8*SIN(($B2-$B17)*PI()/180)*SIN(L6*PI()/180)))/((COS($B2*PI()/180)*COS(L6*PI()/180)*SIN(L7*PI()/180))+((PI()/180)*L7*SIN($B2*PI()/180)*SIN(L6*PI()/180)))) -> 1.0957738 | ... P17: =(((COS(($B2-$B17)*PI()/180)*COS(P6*PI()/180)*SIN(AE8*PI()/180))+((PI()/180)*AE8*SIN(($B2-$B17)*PI()/180)*SIN(P6*PI()/180)))/((COS($B2*PI()/180)*COS(P6*PI()/180)*SIN(P7*PI()/180))+((PI()/180)*P7*SIN($B2*PI()/180)*SIN(P6*PI()/180)))) -> 2.1870499 | S17: =$A$12&TEXT(B26," - ")&B26 -> Beta - 45 | T17: =MIN(DEGREES(ACOS((-TAN($B2*PI()/180))*TAN(E6*PI()/180))),DEGREES(ACOS((-TAN(($B2-$B26)*PI()/180))*TAN(E6*PI()/180)))) -> 64.357072 | U17: =MIN(DEGREES(ACOS((-TAN($B2*PI()/180))*TAN(F6*PI()/180))),DEGREES(ACOS((-TAN(($B2-$B26)*PI()/180))*TAN(F6*PI()/180)))) -> 74.902424 | V17: =MIN(DEGREES(ACOS((-TAN($B2*PI()/180))*TAN(G6*PI()/180))),DEGREES(ACOS((-TAN(($B2-$B26)*PI()/180))*TAN(G6*PI()/180)))) -> 87.259767 | W17: =MIN(DEGREES(ACOS((-TAN($B2*PI()/180))*TAN(H6*PI()/180))),DEGREES(ACOS((-TAN(($B2-$B26)*PI()/180))*TAN(H6*PI()/180)))) -> 90.589412 | X17: =MIN(DEGREES(ACOS((-TAN($B2*PI()/180))*TAN(I6*PI()/180))),DEGREES(ACOS((-TAN(($B2-$B26)*PI()/180))*TAN(I6*PI()/180)))) -> 91.209598 | Y17: =MIN(DEGREES(ACOS((-TAN($B2*PI()/180))*TAN(J6*PI()/180))),DEGREES(ACOS((-TAN(($B2-$B26)*PI()/180))*TAN(J6*PI()/180)))) -> 91.515288 | Z17: =MIN(DEGREES(ACOS((-TAN($B2*PI()/180))*TAN(K6*PI()/180))),DEGREES(ACOS((-TAN(($B2-$B26)*PI()/180))*TAN(K6*PI()/180)))) -> 91.377688 | AA17: =MIN(DEGREES(ACOS((-TAN($B2*PI()/180))*TAN(L6*PI()/180))),DEGREES(ACOS((-TAN(($B2-$B26)*PI()/180))*TAN(L6*PI()/180)))) -> 90.850448 | ... AE17: =MIN(DEGREES(ACOS((-TAN($B2*PI()/180))*TAN(P6*PI()/180))),DEGREES(ACOS((-TAN(($B2-$B26)*PI()/180))*TAN(P6*PI()/180)))) -> 61.198025
B18: =B17+3 -> 21 | D18: ="RbBar at Beta = "&B18 -> RbBar at Beta = 21 | E18: =(((COS(($B2-$B18)*PI()/180)*COS(E6*PI()/180)*SIN(T9*PI()/180))+((PI()/180)*T9*SIN(($B2-$B18)*PI()/180)*SIN(E6*PI()/180)))/((COS($B2*PI()/180)*COS(E6*PI()/180)*SIN(E7*PI()/180))+((PI()/180)*E7*SIN($B2*PI()/180)*SIN(E6*PI()/180)))) -> 2.1845259 | F18: =(((COS(($B2-$B18)*PI()/180)*COS(F6*PI()/180)*SIN(U9*PI()/180))+((PI()/180)*U9*SIN(($B2-$B18)*PI()/180)*SIN(F6*PI()/180)))/((COS($B2*PI()/180)*COS(F6*PI()/180)*SIN(F7*PI()/180))+((PI()/180)*F7*SIN($B2*PI()/180)*SIN(F6*PI()/180)))) -> 1.7328646 | G18: =(((COS(($B2-$B18)*PI()/180)*COS(G6*PI()/180)*SIN(V9*PI()/180))+((PI()/180)*V9*SIN(($B2-$B18)*PI()/180)*SIN(G6*PI()/180)))/((COS($B2*PI()/180)*COS(G6*PI()/180)*SIN(G7*PI()/180))+((PI()/180)*G7*SIN($B2*PI()/180)*SIN(G6*PI()/180)))) -> 1.3961431 | H18: =(((COS(($B2-$B18)*PI()/180)*COS(H6*PI()/180)*SIN(W9*PI()/180))+((PI()/180)*W9*SIN(($B2-$B18)*PI()/180)*SIN(H6*PI()/180)))/((COS($B2*PI()/180)*COS(H6*PI()/180)*SIN(H7*PI()/180))+((PI()/180)*H7*SIN($B2*PI()/180)*SIN(H6*PI()/180)))) -> 1.1628539 | I18: =(((COS(($B2-$B18)*PI()/180)*COS(I6*PI()/180)*SIN(X9*PI()/180))+((PI()/180)*X9*SIN(($B2-$B18)*PI()/180)*SIN(I6*PI()/180)))/((COS($B2*PI()/180)*COS(I6*PI()/180)*SIN(I7*PI()/180))+((PI()/180)*I7*SIN($B2*PI()/180)*SIN(I6*PI()/180)))) -> 1.031889 | J18: =(((COS(($B2-$B18)*PI()/180)*COS(J6*PI()/180)*SIN(Y9*PI()/180))+((PI()/180)*Y9*SIN(($B2-$B18)*PI()/180)*SIN(J6*PI()/180)))/((COS($B2*PI()/180)*COS(J6*PI()/180)*SIN(J7*PI()/180))+((PI()/180)*J7*SIN($B2*PI()/180)*SIN(J6*PI()/180)))) -> 0.98050333 | K18: =(((COS(($B2-$B18)*PI()/180)*COS(K6*PI()/180)*SIN(Z9*PI()/180))+((PI()/180)*Z9*SIN(($B2-$B18)*PI()/180)*SIN(K6*PI()/180)))/((COS($B2*PI()/180)*COS(K6*PI()/180)*SIN(K7*PI()/180))+((PI()/180)*K7*SIN($B2*PI()/180)*SIN(K6*PI()/180)))) -> 1.0027748 | L18: =(((COS(($B2-$B18)*PI()/180)*COS(L6*PI()/180)*SIN(AA9*PI()/180))+((PI()/180)*AA9*SIN(($B2-$B18)*PI()/180)*SIN(L6*PI()/180)))/((COS($B2*PI()/180)*COS(L6*PI()/180)*SIN(L7*PI()/180))+((PI()/180)*L7*SIN($B2*PI()/180)*SIN(L6*PI()/180)))) -> 1.1025252 | ... P18: =(((COS(($B2-$B18)*PI()/180)*COS(P6*PI()/180)*SIN(AE9*PI()/180))+((PI()/180)*AE9*SIN(($B2-$B18)*PI()/180)*SIN(P6*PI()/180)))/((COS($B2*PI()/180)*COS(P6*PI()/180)*SIN(P7*PI()/180))+((PI()/180)*P7*SIN($B2*PI()/180)*SIN(P6*PI()/180)))) -> 2.3669657 | S18: =$A$12&TEXT(B27," - ")&B27 -> Beta - 48 | T18: =MIN(DEGREES(ACOS((-TAN($B2*PI()/180))*TAN(E6*PI()/180))),DEGREES(ACOS((-TAN(($B2-$B27)*PI()/180))*TAN(E6*PI()/180)))) -> 64.357072 | U18: =MIN(DEGREES(ACOS((-TAN($B2*PI()/180))*TAN(F6*PI()/180))),DEGREES(ACOS((-TAN(($B2-$B27)*PI()/180))*TAN(F6*PI()/180)))) -> 74.902424 | V18: =MIN(DEGREES(ACOS((-TAN($B2*PI()/180))*TAN(G6*PI()/180))),DEGREES(ACOS((-TAN(($B2-$B27)*PI()/180))*TAN(G6*PI()/180)))) -> 87.259767 | W18: =MIN(DEGREES(ACOS((-TAN($B2*PI()/180))*TAN(H6*PI()/180))),DEGREES(ACOS((-TAN(($B2-$B27)*PI()/180))*TAN(H6*PI()/180)))) -> 90.091202 | X18: =MIN(DEGREES(ACOS((-TAN($B2*PI()/180))*TAN(I6*PI()/180))),DEGREES(ACOS((-TAN(($B2-$B27)*PI()/180))*TAN(I6*PI()/180)))) -> 90.187155 | Y18: =MIN(DEGREES(ACOS((-TAN($B2*PI()/180))*TAN(J6*PI()/180))),DEGREES(ACOS((-TAN(($B2-$B27)*PI()/180))*TAN(J6*PI()/180)))) -> 90.234443 | Z18: =MIN(DEGREES(ACOS((-TAN($B2*PI()/180))*TAN(K6*PI()/180))),DEGREES(ACOS((-TAN(($B2-$B27)*PI()/180))*TAN(K6*PI()/180)))) -> 90.213158 | AA18: =MIN(DEGREES(ACOS((-TAN($B2*PI()/180))*TAN(L6*PI()/180))),DEGREES(ACOS((-TAN(($B2-$B27)*PI()/180))*TAN(L6*PI()/180)))) -> 90.13159 | ... AE18: =MIN(DEGREES(ACOS((-TAN($B2*PI()/180))*TAN(P6*PI()/180))),DEGREES(ACOS((-TAN(($B2-$B27)*PI()/180))*TAN(P6*PI()/180)))) -> 61.198025
B19: =B18+3 -> 24 | D19: ="RbBar at Beta = "&B19 -> RbBar at Beta = 24 | E19: =(((COS(($B2-$B19)*PI()/180)*COS(E6*PI()/180)*SIN(T10*PI()/180))+((PI()/180)*T10*SIN(($B2-$B19)*PI()/180)*SIN(E6*PI()/180)))/((COS($B2*PI()/180)*COS(E6*PI()/180)*SIN(E7*PI()/180))+((PI()/180)*E7*SIN($B2*PI()/180)*SIN(E6*PI()/180)))) -> 2.3333302 | F19: =(((COS(($B2-$B19)*PI()/180)*COS(F6*PI()/180)*SIN(U10*PI()/180))+((PI()/180)*U10*SIN(($B2-$B19)*PI()/180)*SIN(F6*PI()/180)))/((COS($B2*PI()/180)*COS(F6*PI()/180)*SIN(F7*PI()/180))+((PI()/180)*F7*SIN($B2*PI()/180)*SIN(F6*PI()/180)))) -> 1.8207085 | G19: =(((COS(($B2-$B19)*PI()/180)*COS(G6*PI()/180)*SIN(V10*PI()/180))+((PI()/180)*V10*SIN(($B2-$B19)*PI()/180)*SIN(G6*PI()/180)))/((COS($B2*PI()/180)*COS(G6*PI()/180)*SIN(G7*PI()/180))+((PI()/180)*G7*SIN($B2*PI()/180)*SIN(G6*PI()/180)))) -> 1.43854 | H19: =(((COS(($B2-$B19)*PI()/180)*COS(H6*PI()/180)*SIN(W10*PI()/180))+((PI()/180)*W10*SIN(($B2-$B19)*PI()/180)*SIN(H6*PI()/180)))/((COS($B2*PI()/180)*COS(H6*PI()/180)*SIN(H7*PI()/180))+((PI()/180)*H7*SIN($B2*PI()/180)*SIN(H6*PI()/180)))) -> 1.1743992 | I19: =(((COS(($B2-$B19)*PI()/180)*COS(I6*PI()/180)*SIN(X10*PI()/180))+((PI()/180)*X10*SIN(($B2-$B19)*PI()/180)*SIN(I6*PI()/180)))/((COS($B2*PI()/180)*COS(I6*PI()/180)*SIN(I7*PI()/180))+((PI()/180)*I7*SIN($B2*PI()/180)*SIN(I6*PI()/180)))) -> 1.0272638 | J19: =(((COS(($B2-$B19)*PI()/180)*COS(J6*PI()/180)*SIN(Y10*PI()/180))+((PI()/180)*Y10*SIN(($B2-$B19)*PI()/180)*SIN(J6*PI()/180)))/((COS($B2*PI()/180)*COS(J6*PI()/180)*SIN(J7*PI()/180))+((PI()/180)*J7*SIN($B2*PI()/180)*SIN(J6*PI()/180)))) -> 0.96986705 | K19: =(((COS(($B2-$B19)*PI()/180)*COS(K6*PI()/180)*SIN(Z10*PI()/180))+((PI()/180)*Z10*SIN(($B2-$B19)*PI()/180)*SIN(K6*PI()/180)))/((COS($B2*PI()/180)*COS(K6*PI()/180)*SIN(K7*PI()/180))+((PI()/180)*K7*SIN($B2*PI()/180)*SIN(K6*PI()/180)))) -> 0.99471609 | L19: =(((COS(($B2-$B19)*PI()/180)*COS(L6*PI()/180)*SIN(AA10*PI()/180))+((PI()/180)*AA10*SIN(($B2-$B19)*PI()/180)*SIN(L6*PI()/180)))/((COS($B2*PI()/180)*COS(L6*PI()/180)*SIN(L7*PI()/180))+((PI()/180)*L7*SIN($B2*PI()/180)*SIN(L6*PI()/180)))) -> 1.1064894 | ... P19: =(((COS(($B2-$B19)*PI()/180)*COS(P6*PI()/180)*SIN(AE10*PI()/180))+((PI()/180)*AE10*SIN(($B2-$B19)*PI()/180)*SIN(P6*PI()/180)))/((COS($B2*PI()/180)*COS(P6*PI()/180)*SIN(P7*PI()/180))+((PI()/180)*P7*SIN($B2*PI()/180)*SIN(P6*PI()/180)))) -> 2.5403938 | S19: =$A$12&TEXT(B28," - ")&B28 -> Beta - 51 | T19: =MIN(DEGREES(ACOS((-TAN($B2*PI()/180))*TAN(E6*PI()/180))),DEGREES(ACOS((-TAN(($B2-$B28)*PI()/180))*TAN(E6*PI()/180)))) -> 64.357072 | U19: =MIN(DEGREES(ACOS((-TAN($B2*PI()/180))*TAN(F6*PI()/180))),DEGREES(ACOS((-TAN(($B2-$B28)*PI()/180))*TAN(F6*PI()/180)))) -> 74.902424 | V19: =MIN(DEGREES(ACOS((-TAN($B2*PI()/180))*TAN(G6*PI()/180))),DEGREES(ACOS((-TAN(($B2-$B28)*PI()/180))*TAN(G6*PI()/180)))) -> 87.259767 | W19: =MIN(DEGREES(ACOS((-TAN($B2*PI()/180))*TAN(H6*PI()/180))),DEGREES(ACOS((-TAN(($B2-$B28)*PI()/180))*TAN(H6*PI()/180)))) -> 89.5935 | X19: =MIN(DEGREES(ACOS((-TAN($B2*PI()/180))*TAN(I6*PI()/180))),DEGREES(ACOS((-TAN(($B2-$B28)*PI()/180))*TAN(I6*PI()/180)))) -> 89.1658 | Y19: =MIN(DEGREES(ACOS((-TAN($B2*PI()/180))*TAN(J6*PI()/180))),DEGREES(ACOS((-TAN(($B2-$B28)*PI()/180))*TAN(J6*PI()/180)))) -> 88.955004 | Z19: =MIN(DEGREES(ACOS((-TAN($B2*PI()/180))*TAN(K6*PI()/180))),DEGREES(ACOS((-TAN(($B2-$B28)*PI()/180))*TAN(K6*PI()/180)))) -> 89.049887 | AA19: =MIN(DEGREES(ACOS((-TAN($B2*PI()/180))*TAN(L6*PI()/180))),DEGREES(ACOS((-TAN(($B2-$B28)*PI()/180))*TAN(L6*PI()/180)))) -> 89.413476 | ... AE19: =MIN(DEGREES(ACOS((-TAN($B2*PI()/180))*TAN(P6*PI()/180))),DEGREES(ACOS((-TAN(($B2-$B28)*PI()/180))*TAN(P6*PI()/180)))) -> 61.198025
B20: =B19+3 -> 27 | D20: ="RbBar at Beta = "&B20 -> RbBar at Beta = 27 | E20: =(((COS(($B2-$B20)*PI()/180)*COS(E6*PI()/180)*SIN(T11*PI()/180))+((PI()/180)*T11*SIN(($B2-$B20)*PI()/180)*SIN(E6*PI()/180)))/((COS($B2*PI()/180)*COS(E6*PI()/180)*SIN(E7*PI()/180))+((PI()/180)*E7*SIN($B2*PI()/180)*SIN(E6*PI()/180)))) -> 2.4757391 | F20: =(((COS(($B2-$B20)*PI()/180)*COS(F6*PI()/180)*SIN(U11*PI()/180))+((PI()/180)*U11*SIN(($B2-$B20)*PI()/180)*SIN(F6*PI()/180)))/((COS($B2*PI()/180)*COS(F6*PI()/180)*SIN(F7*PI()/180))+((PI()/180)*F7*SIN($B2*PI()/180)*SIN(F6*PI()/180)))) -> 1.903562 | G20: =(((COS(($B2-$B20)*PI()/180)*COS(G6*PI()/180)*SIN(V11*PI()/180))+((PI()/180)*V11*SIN(($B2-$B20)*PI()/180)*SIN(G6*PI()/180)))/((COS($B2*PI()/180)*COS(G6*PI()/180)*SIN(G7*PI()/180))+((PI()/180)*G7*SIN($B2*PI()/180)*SIN(G6*PI()/180)))) -> 1.4769938 | H20: =(((COS(($B2-$B20)*PI()/180)*COS(H6*PI()/180)*SIN(W11*PI()/180))+((PI()/180)*W11*SIN(($B2-$B20)*PI()/180)*SIN(H6*PI()/180)))/((COS($B2*PI()/180)*COS(H6*PI()/180)*SIN(H7*PI()/180))+((PI()/180)*H7*SIN($B2*PI()/180)*SIN(H6*PI()/180)))) -> 1.1828414 | I20: =(((COS(($B2-$B20)*PI()/180)*COS(I6*PI()/180)*SIN(X11*PI()/180))+((PI()/180)*X11*SIN(($B2-$B20)*PI()/180)*SIN(I6*PI()/180)))/((COS($B2*PI()/180)*COS(I6*PI()/180)*SIN(I7*PI()/180))+((PI()/180)*I7*SIN($B2*PI()/180)*SIN(I6*PI()/180)))) -> 1.0202072 | J20: =(((COS(($B2-$B20)*PI()/180)*COS(J6*PI()/180)*SIN(Y11*PI()/180))+((PI()/180)*Y11*SIN(($B2-$B20)*PI()/180)*SIN(J6*PI()/180)))/((COS($B2*PI()/180)*COS(J6*PI()/180)*SIN(J7*PI()/180))+((PI()/180)*J7*SIN($B2*PI()/180)*SIN(J6*PI()/180)))) -> 0.95711614 | K20: =(((COS(($B2-$B20)*PI()/180)*COS(K6*PI()/180)*SIN(Z11*PI()/180))+((PI()/180)*Z11*SIN(($B2-$B20)*PI()/180)*SIN(K6*PI()/180)))/((COS($B2*PI()/180)*COS(K6*PI()/180)*SIN(K7*PI()/180))+((PI()/180)*K7*SIN($B2*PI()/180)*SIN(K6*PI()/180)))) -> 0.98440136 | L20: =(((COS(($B2-$B20)*PI()/180)*COS(L6*PI()/180)*SIN(AA11*PI()/180))+((PI()/180)*AA11*SIN(($B2-$B20)*PI()/180)*SIN(L6*PI()/180)))/((COS($B2*PI()/180)*COS(L6*PI()/180)*SIN(L7*PI()/180))+((PI()/180)*L7*SIN($B2*PI()/180)*SIN(L6*PI()/180)))) -> 1.1076376 | ... P20: =(((COS(($B2-$B20)*PI()/180)*COS(P6*PI()/180)*SIN(AE11*PI()/180))+((PI()/180)*AE11*SIN(($B2-$B20)*PI()/180)*SIN(P6*PI()/180)))/((COS($B2*PI()/180)*COS(P6*PI()/180)*SIN(P7*PI()/180))+((PI()/180)*P7*SIN($B2*PI()/180)*SIN(P6*PI()/180)))) -> 2.7068589 | S20: =$A$12&TEXT(B29," - ")&B29 -> Beta - 54 | T20: =MIN(DEGREES(ACOS((-TAN($B2*PI()/180))*TAN(E6*PI()/180))),DEGREES(ACOS((-TAN(($B2-$B29)*PI()/180))*TAN(E6*PI()/180)))) -> 64.357072 | U20: =MIN(DEGREES(ACOS((-TAN($B2*PI()/180))*TAN(F6*PI()/180))),DEGREES(ACOS((-TAN(($B2-$B29)*PI()/180))*TAN(F6*PI()/180)))) -> 74.902424 | V20: =MIN(DEGREES(ACOS((-TAN($B2*PI()/180))*TAN(G6*PI()/180))),DEGREES(ACOS((-TAN(($B2-$B29)*PI()/180))*TAN(G6*PI()/180)))) -> 87.259767 | W20: =MIN(DEGREES(ACOS((-TAN($B2*PI()/180))*TAN(H6*PI()/180))),DEGREES(ACOS((-TAN(($B2-$B29)*PI()/180))*TAN(H6*PI()/180)))) -> 89.09353 | X20: =MIN(DEGREES(ACOS((-TAN($B2*PI()/180))*TAN(I6*PI()/180))),DEGREES(ACOS((-TAN(($B2-$B29)*PI()/180))*TAN(I6*PI()/180)))) -> 88.139586 | Y20: =MIN(DEGREES(ACOS((-TAN($B2*PI()/180))*TAN(J6*PI()/180))),DEGREES(ACOS((-TAN(($B2-$B29)*PI()/180))*TAN(J6*PI()/180)))) -> 87.669287 | Z20: =MIN(DEGREES(ACOS((-TAN($B2*PI()/180))*TAN(K6*PI()/180))),DEGREES(ACOS((-TAN(($B2-$B29)*PI()/180))*TAN(K6*PI()/180)))) -> 87.880992 | AA20: =MIN(DEGREES(ACOS((-TAN($B2*PI()/180))*TAN(L6*PI()/180))),DEGREES(ACOS((-TAN(($B2-$B29)*PI()/180))*TAN(L6*PI()/180)))) -> 88.692041 | ... AE20: =MIN(DEGREES(ACOS((-TAN($B2*PI()/180))*TAN(P6*PI()/180))),DEGREES(ACOS((-TAN(($B2-$B29)*PI()/180))*TAN(P6*PI()/180)))) -> 61.198025
B21: =B20+3 -> 30 | D21: ="RbBar at Beta = "&B21 -> RbBar at Beta = 30 | E21: =(((COS(($B2-$B21)*PI()/180)*COS(E6*PI()/180)*SIN(T12*PI()/180))+((PI()/180)*T12*SIN(($B2-$B21)*PI()/180)*SIN(E6*PI()/180)))/((COS($B2*PI()/180)*COS(E6*PI()/180)*SIN(E7*PI()/180))+((PI()/180)*E7*SIN($B2*PI()/180)*SIN(E6*PI()/180)))) -> 2.6113621 | F21: =(((COS(($B2-$B21)*PI()/180)*COS(F6*PI()/180)*SIN(U12*PI()/180))+((PI()/180)*U12*SIN(($B2-$B21)*PI()/180)*SIN(F6*PI()/180)))/((COS($B2*PI()/180)*COS(F6*PI()/180)*SIN(F7*PI()/180))+((PI()/180)*F7*SIN($B2*PI()/180)*SIN(F6*PI()/180)))) -> 1.9811979 | G21: =(((COS(($B2-$B21)*PI()/180)*COS(G6*PI()/180)*SIN(V12*PI()/180))+((PI()/180)*V12*SIN(($B2-$B21)*PI()/180)*SIN(G6*PI()/180)))/((COS($B2*PI()/180)*COS(G6*PI()/180)*SIN(G7*PI()/180))+((PI()/180)*G7*SIN($B2*PI()/180)*SIN(G6*PI()/180)))) -> 1.5113994 | H21: =(((COS(($B2-$B21)*PI()/180)*COS(H6*PI()/180)*SIN(W12*PI()/180))+((PI()/180)*W12*SIN(($B2-$B21)*PI()/180)*SIN(H6*PI()/180)))/((COS($B2*PI()/180)*COS(H6*PI()/180)*SIN(H7*PI()/180))+((PI()/180)*H7*SIN($B2*PI()/180)*SIN(H6*PI()/180)))) -> 1.1881496 | I21: =(((COS(($B2-$B21)*PI()/180)*COS(I6*PI()/180)*SIN(X12*PI()/180))+((PI()/180)*X12*SIN(($B2-$B21)*PI()/180)*SIN(I6*PI()/180)))/((COS($B2*PI()/180)*COS(I6*PI()/180)*SIN(I7*PI()/180))+((PI()/180)*I7*SIN($B2*PI()/180)*SIN(I6*PI()/180)))) -> 1.0107125 | J21: =(((COS(($B2-$B21)*PI()/180)*COS(J6*PI()/180)*SIN(Y12*PI()/180))+((PI()/180)*Y12*SIN(($B2-$B21)*PI()/180)*SIN(J6*PI()/180)))/((COS($B2*PI()/180)*COS(J6*PI()/180)*SIN(J7*PI()/180))+((PI()/180)*J7*SIN($B2*PI()/180)*SIN(J6*PI()/180)))) -> 0.9422478 | K21: =(((COS(($B2-$B21)*PI()/180)*COS(K6*PI()/180)*SIN(Z12*PI()/180))+((PI()/180)*Z12*SIN(($B2-$B21)*PI()/180)*SIN(K6*PI()/180)))/((COS($B2*PI()/180)*COS(K6*PI()/180)*SIN(K7*PI()/180))+((PI()/180)*K7*SIN($B2*PI()/180)*SIN(K6*PI()/180)))) -> 0.9718266 | L21: =(((COS(($B2-$B21)*PI()/180)*COS(L6*PI()/180)*SIN(AA12*PI()/180))+((PI()/180)*AA12*SIN(($B2-$B21)*PI()/180)*SIN(L6*PI()/180)))/((COS($B2*PI()/180)*COS(L6*PI()/180)*SIN(L7*PI()/180))+((PI()/180)*L7*SIN($B2*PI()/180)*SIN(L6*PI()/180)))) -> 1.1059525 | ... P21: =(((COS(($B2-$B21)*PI()/180)*COS(P6*PI()/180)*SIN(AE12*PI()/180))+((PI()/180)*AE12*SIN(($B2-$B21)*PI()/180)*SIN(P6*PI()/180)))/((COS($B2*PI()/180)*COS(P6*PI()/180)*SIN(P7*PI()/180))+((PI()/180)*P7*SIN($B2*PI()/180)*SIN(P6*PI()/180)))) -> 2.8659046 | S21: =$A$12&TEXT(B30," - ")&B30 -> Beta - 57 | T21: =MIN(DEGREES(ACOS((-TAN($B2*PI()/180))*TAN(E6*PI()/180))),DEGREES(ACOS((-TAN(($B2-$B30)*PI()/180))*TAN(E6*PI()/180)))) -> 64.357072 | U21: =MIN(DEGREES(ACOS((-TAN($B2*PI()/180))*TAN(F6*PI()/180))),DEGREES(ACOS((-TAN(($B2-$B30)*PI()/180))*TAN(F6*PI()/180)))) -> 74.902424 | V21: =MIN(DEGREES(ACOS((-TAN($B2*PI()/180))*TAN(G6*PI()/180))),DEGREES(ACOS((-TAN(($B2-$B30)*PI()/180))*TAN(G6*PI()/180)))) -> 87.259767 | W21: =MIN(DEGREES(ACOS((-TAN($B2*PI()/180))*TAN(H6*PI()/180))),DEGREES(ACOS((-TAN(($B2-$B30)*PI()/180))*TAN(H6*PI()/180)))) -> 88.588464 | X21: =MIN(DEGREES(ACOS((-TAN($B2*PI()/180))*TAN(I6*PI()/180))),DEGREES(ACOS((-TAN(($B2-$B30)*PI()/180))*TAN(I6*PI()/180)))) -> 87.102451 | Y21: =MIN(DEGREES(ACOS((-TAN($B2*PI()/180))*TAN(J6*PI()/180))),DEGREES(ACOS((-TAN(($B2-$B30)*PI()/180))*TAN(J6*PI()/180)))) -> 86.369454 | Z21: =MIN(DEGREES(ACOS((-TAN($B2*PI()/180))*TAN(K6*PI()/180))),DEGREES(ACOS((-TAN(($B2-$B30)*PI()/180))*TAN(K6*PI()/180)))) -> 86.699451 | AA21: =MIN(DEGREES(ACOS((-TAN($B2*PI()/180))*TAN(L6*PI()/180))),DEGREES(ACOS((-TAN(($B2-$B30)*PI()/180))*TAN(L6*PI()/180)))) -> 87.963144 | ... AE21: =MIN(DEGREES(ACOS((-TAN($B2*PI()/180))*TAN(P6*PI()/180))),DEGREES(ACOS((-TAN(($B2-$B30)*PI()/180))*TAN(P6*PI()/180)))) -> 61.198025
B22: =B21+3 -> 33 | D22: ="RbBar at Beta = "&B22 -> RbBar at Beta = 33 | E22: =(((COS(($B2-$B22)*PI()/180)*COS(E6*PI()/180)*SIN(T13*PI()/180))+((PI()/180)*T13*SIN(($B2-$B22)*PI()/180)*SIN(E6*PI()/180)))/((COS($B2*PI()/180)*COS(E6*PI()/180)*SIN(E7*PI()/180))+((PI()/180)*E7*SIN($B2*PI()/180)*SIN(E6*PI()/180)))) -> 2.7398276 | F22: =(((COS(($B2-$B22)*PI()/180)*COS(F6*PI()/180)*SIN(U13*PI()/180))+((PI()/180)*U13*SIN(($B2-$B22)*PI()/180)*SIN(F6*PI()/180)))/((COS($B2*PI()/180)*COS(F6*PI()/180)*SIN(F7*PI()/180))+((PI()/180)*F7*SIN($B2*PI()/180)*SIN(F6*PI()/180)))) -> 2.0534035 | G22: =(((COS(($B2-$B22)*PI()/180)*COS(G6*PI()/180)*SIN(V13*PI()/180))+((PI()/180)*V13*SIN(($B2-$B22)*PI()/180)*SIN(G6*PI()/180)))/((COS($B2*PI()/180)*COS(G6*PI()/180)*SIN(G7*PI()/180))+((PI()/180)*G7*SIN($B2*PI()/180)*SIN(G6*PI()/180)))) -> 1.5416623 | H22: =(((COS(($B2-$B22)*PI()/180)*COS(H6*PI()/180)*SIN(W13*PI()/180))+((PI()/180)*W13*SIN(($B2-$B22)*PI()/180)*SIN(H6*PI()/180)))/((COS($B2*PI()/180)*COS(H6*PI()/180)*SIN(H7*PI()/180))+((PI()/180)*H7*SIN($B2*PI()/180)*SIN(H6*PI()/180)))) -> 1.1903032 | I22: =(((COS(($B2-$B22)*PI()/180)*COS(I6*PI()/180)*SIN(X13*PI()/180))+((PI()/180)*X13*SIN(($B2-$B22)*PI()/180)*SIN(I6*PI()/180)))/((COS($B2*PI()/180)*COS(I6*PI()/180)*SIN(I7*PI()/180))+((PI()/180)*I7*SIN($B2*PI()/180)*SIN(I6*PI()/180)))) -> 0.99878494 | J22: =(((COS(($B2-$B22)*PI()/180)*COS(J6*PI()/180)*SIN(Y13*PI()/180))+((PI()/180)*Y13*SIN(($B2-$B22)*PI()/180)*SIN(J6*PI()/180)))/((COS($B2*PI()/180)*COS(J6*PI()/180)*SIN(J7*PI()/180))+((PI()/180)*J7*SIN($B2*PI()/180)*SIN(J6*PI()/180)))) -> 0.92527258 | K22: =(((COS(($B2-$B22)*PI()/180)*COS(K6*PI()/180)*SIN(Z13*PI()/180))+((PI()/180)*Z13*SIN(($B2-$B22)*PI()/180)*SIN(K6*PI()/180)))/((COS($B2*PI()/180)*COS(K6*PI()/180)*SIN(K7*PI()/180))+((PI()/180)*K7*SIN($B2*PI()/180)*SIN(K6*PI()/180)))) -> 0.95700043 | L22: =(((COS(($B2-$B22)*PI()/180)*COS(L6*PI()/180)*SIN(AA13*PI()/180))+((PI()/180)*AA13*SIN(($B2-$B22)*PI()/180)*SIN(L6*PI()/180)))/((COS($B2*PI()/180)*COS(L6*PI()/180)*SIN(L7*PI()/180))+((PI()/180)*L7*SIN($B2*PI()/180)*SIN(L6*PI()/180)))) -> 1.1014271 | ... P22: =(((COS(($B2-$B22)*PI()/180)*COS(P6*PI()/180)*SIN(AE13*PI()/180))+((PI()/180)*AE13*SIN(($B2-$B22)*PI()/180)*SIN(P6*PI()/180)))/((COS($B2*PI()/180)*COS(P6*PI()/180)*SIN(P7*PI()/180))+((PI()/180)*P7*SIN($B2*PI()/180)*SIN(P6*PI()/180)))) -> 3.0170952 | S22: =$A$12&TEXT(B31," - ")&B31 -> Beta - 60 | T22: =MIN(DEGREES(ACOS((-TAN($B2*PI()/180))*TAN(E6*PI()/180))),DEGREES(ACOS((-TAN(($B2-$B31)*PI()/180))*TAN(E6*PI()/180)))) -> 64.357072 | U22: =MIN(DEGREES(ACOS((-TAN($B2*PI()/180))*TAN(F6*PI()/180))),DEGREES(ACOS((-TAN(($B2-$B31)*PI()/180))*TAN(F6*PI()/180)))) -> 74.902424 | V22: =MIN(DEGREES(ACOS((-TAN($B2*PI()/180))*TAN(G6*PI()/180))),DEGREES(ACOS((-TAN(($B2-$B31)*PI()/180))*TAN(G6*PI()/180)))) -> 87.259767 | W22: =MIN(DEGREES(ACOS((-TAN($B2*PI()/180))*TAN(H6*PI()/180))),DEGREES(ACOS((-TAN(($B2-$B31)*PI()/180))*TAN(H6*PI()/180)))) -> 88.07536 | X22: =MIN(DEGREES(ACOS((-TAN($B2*PI()/180))*TAN(I6*PI()/180))),DEGREES(ACOS((-TAN(($B2-$B31)*PI()/180))*TAN(I6*PI()/180)))) -> 86.048064 | Y22: =MIN(DEGREES(ACOS((-TAN($B2*PI()/180))*TAN(J6*PI()/180))),DEGREES(ACOS((-TAN(($B2-$B31)*PI()/180))*TAN(J6*PI()/180)))) -> 85.047299 | Z22: =MIN(DEGREES(ACOS((-TAN($B2*PI()/180))*TAN(K6*PI()/180))),DEGREES(ACOS((-TAN(($B2-$B31)*PI()/180))*TAN(K6*PI()/180)))) -> 85.497925 | AA22: =MIN(DEGREES(ACOS((-TAN($B2*PI()/180))*TAN(L6*PI()/180))),DEGREES(ACOS((-TAN(($B2-$B31)*PI()/180))*TAN(L6*PI()/180)))) -> 87.222469 | ... AE22: =MIN(DEGREES(ACOS((-TAN($B2*PI()/180))*TAN(P6*PI()/180))),DEGREES(ACOS((-TAN(($B2-$B31)*PI()/180))*TAN(P6*PI()/180)))) -> 61.198025
